File: S16-M-H_T.dat
[Header]
; MPMS3 Data File (default extension .dat)
; Copyright (c) 2007, Quantum Design, Inc. All rights reserved.
TITLE,
FILEOPENTIME,3884591358.92161,02/03/2023,1:09 pm
BYAPP,MPMS3 w/ AC,1.0,1.1
INFO,MPMS3 Measurement Release 1.1.16 Build 424, MultiVu Release 2.3.4.19,APPNAME
INFO,Linear Motor Servo Controller,MOTOR_MODULE_NAME
INFO,3101-100 N0,MOTOR_HW_VERSION
INFO,MMC1038,MOTOR_SERIAL_NUMBER
INFO,01.04.28,MOTOR_SOFTWARE_VERSION
INFO,Quantum Design Squid Module,SQUID_MODULE_NAME
INFO,3101-501 B0,SQUID_HW_VERSION
INFO,SQM266,SQUID_SERIAL_NUMBER
INFO,01.03.04,SQUID_SOFTWARE_VERSION
INFO,SQUID AC,AC_MODULE_NAME
INFO,3101-401 G0,AC_HW_VERSION
INFO,SAC261,AC_SERIAL_NUMBER
INFO,SQUID AC 00.95.07,AC_SOFTWARE_VERSION
INFO,TCI280,COIL_SERIAL_NUMBER
INFO,0,MOMENT_UNITS
INFO,Nb-Y-[Ho8-Er6]_10-TaN,SAMPLE_MATERIAL
INFO,,SAMPLE_COMMENT
INFO,,SAMPLE_MASS
INFO,,SAMPLE_VOLUME
INFO,,SAMPLE_MOLECULAR_WEIGHT
INFO,,SAMPLE_SIZE
INFO,,SAMPLE_SHAPE
INFO,Quartz,SAMPLE_HOLDER
INFO,Standard,SAMPLE_HOLDER_DETAIL
INFO,67,SAMPLE_OFFSET
DATATYPE,COMMENT,1
DATATYPE,TIME,2
STARTUPAXIS,X,2
STARTUPAXIS,Y1,5
FIELDGROUP, VSM,2,3,4,5,6,8,9,10,11,14,15
FIELDGROUP, DC, 2,3,4,14,56,57,58,59,60,61,62,63,64,65,66,67,68,69
FIELDGROUP, AC, 2,3,4,11,16,17,18,19,20,21,22,23,24,25,26,27,28,29,30
STARTUPGROUP, All
[Data]
Comment,Time Stamp (sec),Temperature (K),Magnetic Field (Oe),Moment (emu),M. Std. Err. (emu),Transport Action,Averaging Time (sec),Frequency (Hz),Peak Amplitude (mm),Center Position (mm),Lockin Signal' (V),Lockin Signal (V),Range,M. Quad. Signal (emu),AC Moment (emu),AC M. Std Err. (emu),AC Phase (deg),AC Phase Std. Err. (deg),AC Susceptibility (emu/Oe),AC Suscept. Std Err. (emu/Oe),AC X' (emu/Oe),AC X' Std Err. (emu/Oe),AC X'' (emu/Oe),AC X'' Std Err. (emu/Oe),AC Drive (Oe),AC Frequency (Hz),AC Averaging Time (sec),AC Cycles,AC Range,AC Measure Type,AC Signal' (V),AC Signal'' (V),AC Trim Coil Ratio,AC Trim Coil Phase,Min. Temperature (K),Max. Temperature (K),Min. Field (Oe),Max. Field (Oe),Mass (grams),Motor Lag (deg),Pressure (Torr),Measure Count,Measurement Number,SQUID Status (code),Motor Status (code),Measure Status (code),Motor Current (amps),Motor Temp. (C),Temp. Status (code),Field Status (code),Chamber Status (code),Chamber Temp (K),Redirection State,Evercool Status,Average Temp (K),Rotation Angle (deg),Rotator state,DC Moment Fixed Ctr (emu),DC Moment Err Fixed Ctr (emu),DC Moment Free Ctr (emu),DC Moment Err Free Ctr (emu),DC Fixed Fit,DC Free Fit,DC Calculated Center (mm),DC Calculated Center Err (mm),DC Scan Length (mm),DC Scan Time (s),DC Number of Points,DC Squid Drift,DC Min V (V),DC Max V (V),DC Scans per Measure,Map 01,Map 02,Map 03,Map 04,Map 05,Map 06,Map 07,Map 08,Map 09,Map 10,Map 11,Map 12,Map 13,Map 14,Map 15,Map 16
,3884593584.68475,1.99992525577545,70000.359375,0.00373971170121855,1.46750361886573E-6,1,2,14.4053468704224,4.99995089566352,34.5899984240532,4.59671837206609,0.705185440416884,10,-2.79023765412043E-6,,,,,,,,,,,,,,,,,,,,,1.99992525577545,1.99992525577545,70000.359375,70000.359375,53.6013481490345,5.938867672217,2.83927893638611,29,1,0,0,1,0.343170166015625,32.7468223571777,1,1,1,1.99992525577545,0,742397504,1.99992525577545,,,,,,,,,,,,,,,,,,,,,,,,,,,,,,,,,
,3884594405.49108,1.99982422590256,5300.216796875,0.00327270614078443,1.26368590972978E-5,1,2,14.4053468704224,4.99988891524741,34.5899984240532,4.01795468745465,0.647389658902227,10,2.21933381274695E-5,,,,,,,,,,,,,,,,,,,,,1.99970376491547,1.99994468688965,5300.216796875,5300.216796875,52.2702347807844,5.93457334933622,2.69974541664124,29,1,0,0,1,0.346145629882812,31.7693061828613,1,1,1,1.99994468688965,0,742397536,1.99982422590256,,,,,,,,,,,,,,,,,,,,,,,,,,,,,,,,,
,3884595023.29772,1.99968677759171,-100.001098632813,0.00186282947898985,7.67538482276375E-6,1,2,14.4053468704224,4.99989479014852,34.5899984240532,2.28830279239454,0.360239409871036,10,5.91451485538337E-6,,,,,,,,,,,,,,,,,,,,,1.99941372871399,1.99995982646942,-100.001098632813,-100.001098632813,52.2635909383709,5.93548517476523,2.66333532333374,29,1,0,0,1,0.346603393554687,32.7468223571777,1,1,1,1.99995982646942,0,742397408,1.99968677759171,,,,,,,,,,,,,,,,,,,,,,,,,,,,,,,,,
,3884595630.63087,2.00016307830811,-5500.31689453125,-0.00200898008955515,8.58684459730803E-6,1,2,14.4053468704224,4.9999315543212,34.5899984240532,-2.4672246577699,-0.392625531833169,10,-9.73009749413017E-6,,,,,,,,,,,,,,,,,,,,,1.9999508857727,2.00037527084351,-5500.31689453125,-5500.31689453125,52.2471767394671,5.93372460318704,2.64784860610962,29,1,0,0,1,0.34210205078125,31.7693061828613,1,1,1,2.00037527084351,0,742397632,2.00016307830811,,,,,,,,,,,,,,,,,,,,,,,,,,,,,,,,,
,3884596407.48458,1.99985748529434,-60000.33203125,-0.00385246040964764,1.09761631590237E-6,1,2,14.4053468704224,4.99999692647338,34.5899984240532,-4.73527785792937,-0.727025380262095,10,2.41061449343956E-6,,,,,,,,,,,,,,,,,,,,,1.99968326091766,2.00003170967102,-60000.33203125,-60000.33203125,53.3817105351306,5.93892130074529,2.63083004951477,29,1,0,0,1,0.343780517578125,32.7468223571777,1,1,1,2.00003170967102,0,742397120,1.99985748529434,,,,,,,,,,,,,,,,,,,,,,,,,,,,,,,,,
,3884597137.68634,1.99987709522247,-5200.36181640625,-0.00323491257808259,1.02773281440571E-5,1,2,14.4053468704224,4.99987828830477,34.5899984240532,-3.97527880358233,-0.615681623718377,10,-2.22178056043716E-6,,,,,,,,,,,,,,,,,,,,,1.99958181381226,2.00017237663269,-5200.36181640625,-5200.36181640625,52.3550414751209,5.93541006796194,2.63234114646912,29,1,0,0,1,0.340423583984375,31.2805480957031,1,1,1,2.00017237663269,0,742397376,1.99987709522247,,,,,,,,,,,,,,,,,,,,,,,,,,,,,,,,,
,3884597744.69825,1.99996799230576,199.904632568359,-0.00180542574636936,8.38816263944875E-6,1,2,14.4053468704224,4.99992242518931,34.5899984240532,-2.21644590628683,-0.357956678474108,10,-1.29050731610203E-5,,,,,,,,,,,,,,,,,,,,,1.999964594841,1.99997138977051,199.904632568359,199.904632568359,52.1815199438517,5.93499078135284,2.62743735313416,29,1,0,0,1,0.3448486328125,30.3030319213867,1,1,1,1.999964594841,0,742397504,1.99996799230576,,,,,,,,,,,,,,,,,,,,,,,,,,,,,,,,,
,3884598336.64932,2.00005424022675,5600.30517578125,0.00220479556796982,9.46109753402455E-6,1,2,14.4053468704224,4.99999171065507,34.5899984240532,2.71082618395179,0.410953630535871,10,-5.55241129813327E-6,,,,,,,,,,,,,,,,,,,,,1.99977779388428,2.00033068656921,5600.30517578125,5600.30517578125,52.2260727694478,5.93433141574779,2.62717247009277,29,1,0,0,1,0.346298217773438,31.7693061828613,1,1,1,2.00033068656921,0,742397472,2.00005424022675,,,,,,,,,,,,,,,,,,,,,,,,,,,,,,,,,
,3884599405.60675,9.99988603591919,50000.2421875,0.00386784201185547,1.09460328665786E-6,1,2,14.4053468704224,4.9999620181246,34.5899984240532,4.75414668635889,0.729864868315251,10,-2.46595483161521E-6,,,,,,,,,,,,,,,,,,,,,9.99987888336182,9.99989318847656,50000.2421875,50000.2421875,52.5946106162652,5.93676544651033,5.06263494491577,29,1,0,0,1,0.34027099609375,31.7693061828613,1,1,1,9.99987888336182,0,742397408,9.99988603591919,,,,,,,,,,,,,,,,,,,,,,,,,,,,,,,,,
,3884600125.18299,9.99987649917603,5100.421875,0.00307820582474987,1.2917914411618E-6,1,2,14.4053468704224,4.99999022248969,34.5899984240532,3.78356778794785,0.581056574313105,10,-1.80620268968207E-6,,,,,,,,,,,,,,,,,,,,,9.99984550476074,9.99990749359131,5100.421875,5100.421875,52.1873821577459,5.9348543940839,5.04537200927734,29,1,0,0,1,0.340728759765625,32.2580642700195,1,1,1,9.99990749359131,0,742397472,9.99987649917603,,,,,,,,,,,,,,,,,,,,,,,,,,,,,,,,,
,3884600735.57189,9.99990081787109,-299.795989990234,0.00135443354443864,3.75063019940185E-7,1,2,14.4053468704224,4.99992967391276,34.5899984240532,1.6646941640005,0.2561567527306,10,-3.94556727303309E-7,,,,,,,,,,,,,,,,,,,,,9.99984645843506,9.99995517730713,-299.795989990234,-299.795989990234,52.0869428930247,5.93478574725723,5.05093479156494,29,1,0,0,1,0.346603393554687,32.2580642700195,1,1,1,9.99995517730713,0,742397504,9.99990081787109,,,,,,,,,,,,,,,,,,,,,,,,,,,,,,,,,
,3884601336.74409,9.99980688095093,-5700.2822265625,-0.00208281209982116,4.48447159073197E-7,1,2,14.4053468704224,4.99991359148531,34.6000008285046,-2.56020047037328,-0.392033122321786,10,2.13333024692078E-6,,,,,,,,,,,,,,,,,,,,,9.99975967407227,9.99985408782959,-5700.2822265625,-5700.2822265625,52.1248518762074,5.93480971228476,5.05098962783814,29,1,0,0,1,0.347137451171875,31.7693061828613,1,1,1,9.99975967407227,0,742397664,9.99980688095093,,,,,,,,,,,,,,,,,,,,,,,,,,,,,,,,,
,3884602144.13104,9.99981498718262,-40000.33203125,-0.0039315019164965,9.01681827120917E-7,1,2,14.4053468704224,4.99995683285436,34.5899984240532,-4.83230027105977,-0.7424395998788,10,2.0483499253908E-6,,,,,,,,,,,,,,,,,,,,,9.99973392486572,9.99989604949951,-40000.33203125,-40000.33203125,52.3050172498901,5.93508438677469,5.04246044158936,29,1,0,0,1,0.341796875,30.3030319213867,1,1,1,9.99989604949951,0,742397152,9.99981498718262,,,,,,,,,,,,,,,,,,,,,,,,,,,,,,,,,
,3884602831.49016,9.99999570846558,-5000.2255859375,-0.00306239378282645,9.8133596370452E-7,1,2,14.4053468704224,4.99995363827049,34.5899984240532,-3.76388764458,-0.579405020753578,10,7.07365766106111E-7,,,,,,,,,,,,,,,,,,,,,9.99996662139893,10.0000247955322,-5000.2255859375,-5000.2255859375,52.3683291599478,5.93547206136456,5.03531885147095,29,1,0,0,1,0.345611572265625,31.7693061828613,1,1,1,9.99996662139893,0,742397376,9.99999570846558,,,,,,,,,,,,,,,,,,,,,,,,,,,,,,,,,
,3884603431.19689,9.99980640411377,399.943450927734,-0.00127891109374114,5.23517787757247E-7,1,2,14.4053468704224,4.99995273472317,34.5899984240532,-1.57195371162377,-0.241409075379895,10,7.51780590579183E-7,,,,,,,,,,,,,,,,,,,,,9.99977397918701,9.99983882904053,399.943450927734,399.943450927734,52.2639817526305,5.93468548566553,5.03931999206543,29,1,0,0,1,0.3411865234375,32.2580642700195,1,1,1,9.99983882904053,0,742397376,9.99980640411377,,,,,,,,,,,,,,,,,,,,,,,,,,,,,,,,,
,3884604044.3611,9.99989938735962,5800.283203125,0.00210022671985863,3.18283589335965E-7,1,2,14.4053468704224,4.99996143793311,34.5899984240532,2.58138928928502,0.396948854651121,10,-8.22773097986096E-7,,,,,,,,,,,,,,,,,,,,,9.99989318847656,9.99990558624268,5800.283203125,5800.283203125,52.2835224656113,5.93464078308997,5.03301429748535,29,1,0,0,1,0.345458984375,34.2131004333496,1,1,1,9.99990558624268,0,742397312,9.99989938735962,,,,,,,,,,,,,,,,,,,,,,,,,,,,,,,,,
,3884604978.57295,20.0008010864258,30000.197265625,0.00366751045266743,9.81741384056788E-7,1,2,14.4053468704224,4.99993918419282,34.5899984240532,4.50782628661632,0.692413013231377,10,-2.04916299914876E-6,,,,,,,,,,,,,,,,,,,,,20.0005302429199,20.0010719299316,30000.197265625,30000.197265625,52.2729704806017,5.93477716511064,5.82011938095093,29,1,0,0,1,0.345993041992188,31.7693061828613,1,1,1,20.0010719299316,0,742397056,20.0008010864258,,,,,,,,,,,,,,,,,,,,,,,,,,,,,,,,,
,3884605658.34195,20.0002994537354,4900.419921875,0.00253364944142471,4.96545295763801E-7,1,2,14.4053468704224,5.00004969897995,34.5899984240532,3.11428002055076,0.478268007909605,10,-1.48949840424701E-6,,,,,,,,,,,,,,,,,,,,,20.0001239776611,20.0004749298096,4900.419921875,4900.419921875,52.1529905028998,5.93485770716584,5.81513118743896,29,1,0,0,1,0.342254638671875,32.2580642700195,1,1,1,20.0001239776611,0,742397472,20.0002994537354,,,,,,,,,,,,,,,,,,,,,,,,,,,,,,,,,
,3884606259.55518,19.9998149871826,-500.029876708984,0.000516444119831118,2.22574851749098E-7,1,2,14.4053468704224,5.00002399972008,34.5899984240532,0.634816423656269,0.0973274231981871,10,-4.33142912473971E-7,,,,,,,,,,,,,,,,,,,,,19.9997577667236,19.9998722076416,-500.029876708984,-500.029876708984,52.2921203793228,5.93450857795304,5.81764936447144,29,1,0,0,1,0.346145629882812,31.7693061828613,1,1,1,19.9997577667236,0,742397664,19.9998149871826,,,,,,,,,,,,,,,,,,,,,,,,,,,,,,,,,
,3884606879.58528,20.0000953674316,-5900.259765625,-0.00172300680374294,3.59457511497751E-7,1,2,14.4053468704224,4.99995178132262,34.5899984240532,-2.1180206390546,-0.323848153492333,10,2.14297683979766E-6,,,,,,,,,,,,,,,,,,,,,19.9999485015869,20.0002422332764,-5900.259765625,-5900.259765625,52.3292477339863,5.93495031652296,5.82572603225708,29,1,0,0,1,0.340728759765625,31.7693061828613,1,1,1,19.9999485015869,0,742397568,20.0000953674316,,,,,,,,,,,,,,,,,,,,,,,,,,,,,,,,,
,3884607726.95548,19.9996528625488,-20000.267578125,-0.00356421408570082,4.94375251734675E-7,1,2,14.4053468704224,4.99998915793265,34.5899984240532,-4.38087395243192,-0.6732398318132,10,1.73153738340415E-6,,,,,,,,,,,,,,,,,,,,,19.9996433258057,19.999662399292,-20000.267578125,-20000.267578125,52.296028521919,5.93505411886193,5.82548952102661,29,1,0,0,1,0.341262817382812,31.7693061828613,1,1,1,19.9996433258057,0,742396864,19.9996528625488,,,,,,,,,,,,,,,,,,,,,,,,,,,,,,,,,
,3884608380.79357,20.0003490447998,-4800.39404296875,-0.00251168825725748,6.23808203190696E-7,1,2,14.4053468704224,5.00001406736783,34.5899984240532,-3.08718005249521,-0.47460646425049,10,1.07896374003649E-6,,,,,,,,,,,,,,,,,,,,,20.0003070831299,20.0003910064697,-4800.39404296875,-4800.39404296875,52.3100978352652,5.93510478861876,5.81200456619263,29,1,0,0,1,0.339126586914063,30.3030319213867,1,1,1,20.0003910064697,0,742397440,20.0003490447998,,,,,,,,,,,,,,,,,,,,,,,,,,,,,,,,,
,3884608985.48214,20.0000820159912,599.945617675781,-0.000444524384907674,1.61610899714041E-6,1,2,14.4053468704224,5.00000338449398,34.5899984240532,-0.546411717462402,-0.0837561099601101,10,3.86709818102715E-7,,,,,,,,,,,,,,,,,,,,,20.0000438690186,20.0001201629639,599.945617675781,599.945617675781,52.3007182930344,5.93466704032199,5.813805103302,29,1,0,0,1,0.346603393554687,31.7693061828613,1,1,1,20.0000438690186,0,742397536,20.0000820159912,,,,,,,,,,,,,,,,,,,,,,,,,,,,,,,,,
,3884609609.02515,19.9991912841797,6000.26123046875,0.00173624591969478,2.77343017538395E-7,1,2,14.4053468704224,5.000015556091,34.5899984240532,2.13426317165547,0.32679428507589,10,-1.79170006129031E-6,,,,,,,,,,,,,,,,,,,,,19.9990921020508,19.9992904663086,6000.26123046875,6000.26123046875,52.4206982707363,5.93474043884863,5.8210244178772,29,1,0,0,1,0.346527099609375,31.2805480957031,1,1,1,19.9990921020508,0,742397568,19.9991912841797,,,,,,,,,,,,,,,,,,,,,,,,,,,,,,,,,
,3884610588.76336,29.9999761581421,10000.3056640625,0.00260863537226446,4.81546998202975E-7,1,2,14.4053468704224,5.00005564224817,34.5899984240532,3.20648338867588,0.492243490445117,10,-1.68016591996102E-6,,,,,,,,,,,,,,,,,,,,,29.9999198913574,30.0000324249268,10000.3056640625,10000.3056640625,52.2284176550055,5.93472015596805,6.18732261657715,29,1,0,0,1,0.34027099609375,30.7917900085449,1,1,1,29.9999198913574,0,742396864,29.9999761581421,,,,,,,,,,,,,,,,,,,,,,,,,,,,,,,,,
,3884611238.43903,30.0000524520874,4700.4052734375,0.0016650018491692,2.75772073214687E-7,1,2,14.4053468704224,5.00001835564375,34.5899984240532,2.04666205797949,0.313557833802506,10,-1.57759630458998E-6,,,,,,,,,,,,,,,,,,,,,30.0000133514404,30.0000915527344,4700.4052734375,4700.4052734375,52.1451742177074,5.93404491397197,6.22174882888794,29,1,0,0,1,0.342178344726562,30.7917900085449,1,1,1,30.0000915527344,0,742397440,30.0000524520874,,,,,,,,,,,,,,,,,,,,,,,,,,,,,,,,,
,3884611850.14986,30.0000886917114,-700.019897460937,-6.60645163249817E-5,5.11162335190089E-8,1,2,14.4053468704224,5.0001318873889,34.5899984240532,-0.081257898966618,-0.0121359028796717,1,3.11518487755193E-7,,,,,,,,,,,,,,,,,,,,,30.0000343322754,30.0001430511475,-700.019897460937,-700.019897460937,52.4046748860921,5.93382385819482,6.22201824188232,29,1,0,0,1,0.3411865234375,32.7468223571777,1,1,1,30.0001430511475,0,742397632,30.0000886917114,,,,,,,,,,,,,,,,,,,,,,,,,,,,,,,,,
,3884612473.29168,30.000002861023,-6100.31103515625,-0.00128310000239001,2.1626881349548E-7,1,2,14.4053468704224,5.00005550257124,34.5899984240532,-1.57724680050602,-0.241563260154368,10,1.27777695885313E-6,,,,,,,,,,,,,,,,,,,,,29.9999008178711,30.0001049041748,-6100.31103515625,-6100.31103515625,52.2557746531786,5.93370058601968,6.2220401763916,29,1,0,0,1,0.341339111328125,30.7917900085449,1,1,1,30.0001049041748,0,742397344,30.000002861023,,,,,,,,,,,,,,,,,,,,,,,,,,,,,,,,,
,3884613350.44514,29.9999408721924,-10000.341796875,-0.00260350215731217,5.08493568247314E-7,1,2,14.4053468704224,5.00010561758477,34.5899984240532,-3.20020673818321,-0.4913566642547,10,1.615870770957E-6,,,,,,,,,,,,,,,,,,,,,29.9999408721924,29.9999408721924,-10000.341796875,-10000.341796875,52.0717011368997,5.93399316901694,6.21283864974976,29,1,0,0,1,0.340805053710937,31.2805480957031,1,1,1,29.9999408721924,0,742397216,29.9999408721924,,,,,,,,,,,,,,,,,,,,,,,,,,,,,,,,,
,3884613970.97564,29.999903678894,-4600.2578125,-0.00163906305960669,1.13331641139038E-6,1,2,14.4053468704224,5.00004596080033,34.5899984240532,-2.01453998325988,-0.310316068692116,10,2.18069243445228E-7,,,,,,,,,,,,,,,,,,,,,29.9998264312744,29.9999809265137,-4600.2578125,-4600.2578125,52.2557746531786,5.93349426891044,6.21831464767456,29,1,0,0,1,0.341033935546875,31.7693061828613,1,1,1,29.9999809265137,0,742397312,29.999903678894,,,,,,,,,,,,,,,,,,,,,,,,,,,,,,,,,
,3884614594.98075,29.9998140335083,800.155151367187,9.32896639646602E-5,4.99882746199276E-8,1,2,14.4053468704224,5.00009818765152,34.5899984240532,0.114720854990081,0.0172815707125208,1,-3.22220681802604E-7,,,,,,,,,,,,,,,,,,,,,29.9997577667236,29.999870300293,800.155151367187,800.155151367187,52.0451257672459,5.93354399962986,6.22216987609863,29,1,0,0,1,0.341949462890625,31.7693061828613,1,1,1,29.999870300293,0,742397280,29.9998140335083,,,,,,,,,,,,,,,,,,,,,,,,,,,,,,,,,
,3884615224.49747,30.0002527236938,6200.43408203125,0.00129449769838702,2.32343347318969E-7,1,2,14.4053468704224,5.00013843421189,34.6000008285046,1.59145141570414,0.242694611424863,10,-2.11906909957071E-6,,,,,,,,,,,,,,,,,,,,,30.0002174377441,30.0002880096436,6200.43408203125,6200.43408203125,52.0169871405536,5.93359426362087,6.21062278747559,29,1,0,0,1,0.347061157226562,30.7917900085449,1,1,1,30.0002880096436,0,742397472,30.0002527236938,,,,,,,,,,,,,,,,,,,,,,,,,,,,,,,,,
,3884616253.82524,50.0000171661377,9900.3408203125,0.0011097253417999,1.65922682199711E-7,1,2,14.4053468704224,5.00006495217007,34.5899984240532,1.36429453570413,0.2078569043248,10,-1.97282925132062E-6,,,,,,,,,,,,,,,,,,,,,49.9999847412109,50.0000495910645,9900.3408203125,9900.3408203125,52.2463951109478,5.93394958694608,6.54791355133057,29,1,0,0,1,0.342864990234375,31.2805480957031,1,1,1,49.9999847412109,0,742397408,50.0000171661377,,,,,,,,,,,,,,,,,,,,,,,,,,,,,,,,,
,3884616888.79351,49.999979019165,4500.37890625,0.000511078743490279,3.63895365304757E-7,1,2,14.4053468704224,5.00009484001086,34.5899984240532,0.628246841283839,0.0962327290389064,10,-4.9816951705934E-7,,,,,,,,,,,,,,,,,,,,,49.9998970031738,50.0000610351562,4500.37890625,4500.37890625,52.013469812217,5.93439054951317,6.5993070602417,29,1,0,0,1,0.342254638671875,31.2805480957031,1,1,1,50.0000610351562,0,742397312,49.999979019165,,,,,,,,,,,,,,,,,,,,,,,,,,,,,,,,,
,3884617629.70094,50.00022315979,-900.095275878906,-0.000137700704815996,4.05571875128265E-8,1,2,14.4053468704224,4.99999882465922,34.5899984240532,-0.169296959413019,-0.0257198270192252,1,3.03140359449871E-7,,,,,,,,,,,,,,,,,,,,,50.0002059936523,50.0002403259277,-900.095275878906,-900.095275878906,52.1651057449478,5.93427006622723,6.61934614181519,29,1,0,0,1,0.342941284179687,31.2805480957031,1,1,1,50.0002403259277,0,742397440,50.00022315979,,,,,,,,,,,,,,,,,,,,,,,,,,,,,,,,,
,3884618243.04583,49.9999179840088,-6300.43505859375,-0.00055395657166582,9.29564806720437E-8,1,2,14.4053468704224,5.00007588373144,34.5899984240532,-0.680928448844941,-0.104452655889401,1,4.20468826968685E-7,,,,,,,,,,,,,,,,,,,,,49.9997787475586,50.000057220459,-6300.43505859375,-6300.43505859375,52.2819592085728,5.93346343926906,6.6230411529541,29,1,0,0,1,0.341033935546875,31.7693061828613,1,1,1,49.9997787475586,0,742397728,49.9999179840088,,,,,,,,,,,,,,,,,,,,,,,,,,,,,,,,,
,3884619166.60142,50.0007266998291,-9800.3759765625,-0.00109559117166455,2.29330863264922E-7,1,2,14.4053468704224,5.00004177806004,34.6000008285046,-1.34681477259255,-0.205821394319716,10,1.44877099699696E-6,,,,,,,,,,,,,,,,,,,,,50.000675201416,50.0007781982422,-9800.3759765625,-9800.3759765625,52.3124427208228,5.93335023817035,6.62058210372925,29,1,0,0,1,0.341567993164063,31.2805480957031,1,1,1,50.000675201416,0,742397472,50.0007266998291,,,,,,,,,,,,,,,,,,,,,,,,,,,,,,,,,
,3884619791.20486,50.0001564025879,-4400.40185546875,-0.000503656844395015,9.59929740749444E-8,1,2,14.4053468704224,5.00008314397703,34.5899984240532,-0.619135540869703,-0.0947432492343486,10,5.65525407801529E-7,,,,,,,,,,,,,,,,,,,,,50.0001068115234,50.0002059936523,-4400.40185546875,-4400.40185546875,52.2057504279478,5.93267815103573,6.62156295776367,29,1,0,0,1,0.341949462890625,32.7468223571777,1,1,1,50.0002059936523,0,742397472,50.0001564025879,,,,,,,,,,,,,,,,,,,,,,,,,,,,,,,,,
,3884620500.46831,49.9993896484375,1000.12072753906,0.000154374123751061,3.70766830167227E-8,1,2,14.4053468704224,5.00012079700159,34.5899984240532,0.189798435225564,0.028862376353788,1,-3.17636225892279E-7,,,,,,,,,,,,,,,,,,,,,49.9993629455566,49.9994163513184,1000.12072753906,1000.12072753906,52.3605128747555,5.93254816677235,6.63129281997681,29,1,0,0,1,0.341644287109375,31.2805480957031,1,1,1,49.9993629455566,0,742397568,49.9993896484375,,,,,,,,,,,,,,,,,,,,,,,,,,,,,,,,,
,3884621116.17147,49.9996967315674,6400.39990234375,0.000560803314719061,1.08451403011495E-7,1,2,14.4053468704224,5.00017826008509,34.5899984240532,0.689328363967732,0.105979034327716,1,-2.36618464555367E-7,,,,,,,,,,,,,,,,,,,,,49.9996147155762,49.9997787475586,6400.39990234375,6400.39990234375,52.2600736100344,5.9329638480642,6.62491369247437,29,1,0,0,1,0.340805053710937,31.7693061828613,1,1,1,49.9996147155762,0,742397504,49.9996967315674,,,,,,,,,,,,,,,,,,,,,,,,,,,,,,,,,
,3884622178.19082,69.9994125366211,9700.3134765625,0.000513368203208624,1.07657047129393E-7,1,2,14.4053468704224,5.00008624907249,34.5899984240532,0.631135686233038,0.0961704960149949,10,-9.01592459415921E-7,,,,,,,,,,,,,,,,,,,,,69.9993362426758,69.9994888305664,9700.3134765625,9700.3134765625,52.4249972275921,5.93302054291586,6.76789665222168,29,1,0,0,1,0.344696044921875,29.8142719268799,1,1,1,69.9993362426758,0,742397536,69.9994125366211,,,,,,,,,,,,,,,,,,,,,,,,,,,,,,,,,
,3884622893.9494,70.0001754760742,4300.2666015625,0.000305241331884164,7.22460085266356E-8,1,2,14.4053468704224,5.00008792322993,34.6000008285046,0.375161978882611,0.0578456407749692,1,4.19160775040169E-9,,,,,,,,,,,,,,,,,,,,,70.0001678466797,70.0001831054687,4300.2666015625,4300.2666015625,52.1975433284959,5.93230645717083,6.79826307296753,29,1,0,0,1,0.346527099609375,31.2805480957031,1,1,1,70.0001678466797,0,742397632,70.0001754760742,,,,,,,,,,,,,,,,,,,,,,,,,,,,,,,,,
,3884623628.99862,69.9998283386231,-1100.28039550781,-0.000153424672535177,2.7795062770256E-8,1,2,14.4053468704224,5.00008782539414,34.5899984240532,-0.188642350977296,-0.0286004702260281,1,3.84132520334239E-7,,,,,,,,,,,,,,,,,,,,,69.9998016357422,69.9998550415039,-1100.28039550781,-1100.28039550781,52.1885546005248,5.93277145914524,6.80915880203247,29,1,0,0,1,0.341720581054687,31.2805480957031,1,1,1,69.9998550415039,0,742397568,69.9998283386231,,,,,,,,,,,,,,,,,,,,,,,,,,,,,,,,,
,3884624224.8399,70.0000953674316,-6500.44921875,-0.000352706999849083,6.66476812685809E-8,1,2,14.4053468704224,5.00009169402539,34.5899984240532,-0.433590647226201,-0.0662587770119927,1,4.68727865132066E-7,,,,,,,,,,,,,,,,,,,,,69.9999923706055,70.0001983642578,-6500.44921875,-6500.44921875,52.3159600491594,5.93298659145243,6.81834077835083,29,1,0,0,1,0.345916748046875,32.7468223571777,1,1,1,69.9999923706055,0,742397024,70.0000953674316,,,,,,,,,,,,,,,,,,,,,,,,,,,,,,,,,
,3884625131.41519,69.9998321533203,-9600.4228515625,-0.000507722409521592,1.16820020704267E-7,1,2,14.4053468704224,5.00006471111313,34.6000008285046,-0.623983190916757,-0.0964601251683279,1,-2.0496445604601E-7,,,,,,,,,,,,,,,,,,,,,69.9996566772461,70.0000076293945,-9600.4228515625,-9600.4228515625,52.2084861277651,5.93371159283383,6.81573915481567,28,1,68,0,0,0.340957641601562,31.2805480957031,1,1,1,69.9996566772461,0,742397600,69.9998321533203,,,,,,,,,,,,,,,,,,,,,,,,,,,,,,,,,
,3884625887.29335,70.0004425048828,-4200.50927734375,-0.000301112589671049,5.7777815133053E-8,1,2,14.4053468704224,5.00010417403037,34.6000008285046,-0.370110917621466,-0.0569223103989252,1,1.10715272500738E-7,,,,,,,,,,,,,,,,,,,,,70.0003433227539,70.0005416870117,-4200.50927734375,-4200.50927734375,52.4421930550152,5.93330545785684,6.82727003097534,29,1,0,0,1,0.3387451171875,30.7917900085449,1,1,1,70.0003433227539,0,742397600,70.0004425048828,,,,,,,,,,,,,,,,,,,,,,,,,,,,,,,,,
,3884626631.03205,70.0004043579102,1200.24487304688,0.000160840132405114,2.9677737992614E-8,1,2,14.4053468704224,5.00010681669245,34.6000008285046,0.197741966430346,0.0301066204494161,1,-3.02096478999845E-7,,,,,,,,,,,,,,,,,,,,,70.0003204345703,70.00048828125,1200.24487304688,1200.24487304688,52.1502548030824,5.93338539936538,6.81801176071167,29,1,0,0,1,0.340499877929687,31.2805480957031,1,1,1,70.00048828125,0,742396960,70.0004043579102,,,,,,,,,,,,,,,,,,,,,,,,,,,,,,,,,
,3884627249.126,69.9997024536133,6600.31640625,0.000354852639871187,7.87726859132189E-8,1,2,14.4053468704224,5.00006101204412,34.6000008285046,0.436198118861209,0.0668330575334112,1,-3.31818044354882E-7,,,,,,,,,,,,,,,,,,,,,69.9996109008789,69.9997940063477,6600.31640625,6600.31640625,52.2030147281305,5.93214073432646,6.82759523391724,29,1,0,0,1,0.340499877929687,30.7917900085449,1,1,1,69.9996109008789,0,742397248,69.9997024536133,,,,,,,,,,,,,,,,,,,,,,,,,,,,,,,,,
,3884628350.99967,100.001792907715,9500.2998046875,0.000276286635668593,9.04581126472873E-8,1,2,14.4053468704224,5.00000461149371,34.6099995076656,0.339590500956595,0.0522038306247782,1,-1.21060741364205E-7,,,,,,,,,,,,,,,,,,,,,100.001708984375,100.001876831055,9500.2998046875,9500.2998046875,52.1412660751113,5.93337527340094,6.92263603210449,29,1,0,0,1,0.350418090820313,31.2805480957031,1,1,1,100.001708984375,0,742397728,100.001792907715,,,,,,,,,,,,,,,,,,,,,,,,,,,,,,,,,
,3884629085.57112,100.000228881836,4100.22802734375,0.000195145428686781,4.68906022631266E-8,1,2,14.4053468704224,5.00001120069234,34.6099995076656,0.239839861268064,0.0369923195625348,1,1.20460132712602E-8,,,,,,,,,,,,,,,,,,,,,100.000144958496,100.000312805176,4100.22802734375,4100.22802734375,52.0502063526209,5.93272742565404,6.95311260223389,27,1,68,0,0,0.3424072265625,29.8142719268799,1,1,1,100.000312805176,0,742397696,100.000228881836,,,,,,,,,,,,,,,,,,,,,,,,,,,,,,,,,
,3884629746.08153,100.002643585205,-1300.29479980469,-0.00013304894749438,3.18489381664932E-8,1,2,14.4053468704224,5.00001285071832,34.6099995076656,-0.163590955495329,-0.0247700672629512,1,3.58803545544593E-7,,,,,,,,,,,,,,,,,,,,,100.00260925293,100.00267791748,-1300.29479980469,-1300.29479980469,52.036918667794,5.93222211349331,6.95995235443115,29,1,0,0,1,0.342025756835937,31.2805480957031,1,1,1,100.00260925293,0,742397216,100.002643585205,,,,,,,,,,,,,,,,,,,,,,,,,,,,,,,,,
,3884630341.27245,100.000297546387,-6700.31787109375,-0.000235427438312448,7.32581466220125E-8,1,2,14.4053468704224,5.00006261941461,34.6099995076656,-0.289445366591416,-0.0440224388251383,1,4.78926977217259E-7,,,,,,,,,,,,,,,,,,,,,100.000152587891,100.000442504883,-6700.31787109375,-6700.31787109375,52.3179141204575,5.93168354680366,6.96655464172363,29,1,0,0,1,0.343017578125,31.2805480957031,1,1,1,100.000152587891,0,742397632,100.000297546387,,,,,,,,,,,,,,,,,,,,,,,,,,,,,,,,,
,3884631261.99633,100.00036239624,-9400.322265625,-0.000275236051096885,1.17743412616572E-7,1,2,14.4053468704224,5.00012855125411,34.6099995076656,-0.33826686452871,-0.0522926320120339,1,-1.11696055211212E-7,,,,,,,,,,,,,,,,,,,,,100.000289916992,100.000434875488,-9400.322265625,-9400.322265625,51.8989612341497,5.93202873121917,6.97692441940308,27,1,68,0,0,0.342941284179687,30.7917900085449,1,1,1,100.000289916992,0,742397600,100.00036239624,,,,,,,,,,,,,,,,,,,,,,,,,,,,,,,,,
,3884632074.65855,100.000667572021,-4000.14135742188,-0.000193663381673899,5.22313723173727E-8,1,2,14.4053468704224,5.00005132345257,34.6099995076656,-0.238008384682655,-0.0367938695742089,1,-7.87380062309774E-8,,,,,,,,,,,,,,,,,,,,,100.000526428223,100.00080871582,-4000.14135742188,-4000.14135742188,52.2589011672555,5.93244685999663,6.98296594619751,29,1,0,0,1,0.345611572265625,29.3255138397217,1,1,1,100.000526428223,0,742397504,100.000667572021,,,,,,,,,,,,,,,,,,,,,,,,,,,,,,,,,
,3884632747.87373,100.001689910889,1400.18615722656,0.000137165420780345,3.95197849741449E-8,1,2,14.4053468704224,4.99999404605115,34.6199981868267,0.168645839107785,0.0255730315944003,1,-3.40024778127541E-7,,,,,,,,,,,,,,,,,,,,,100.001434326172,100.001945495605,1400.18615722656,1400.18615722656,52.1209437336113,5.93252742356624,6.98269701004028,29,1,0,0,1,0.345840454101562,31.2805480957031,1,1,1,100.001434326172,0,742397632,100.001689910889,,,,,,,,,,,,,,,,,,,,,,,,,,,,,,,,,
,3884633363.62447,99.9998283386231,6800.3671875,0.000237090991920376,7.93780932144713E-8,1,2,14.4053468704224,4.99987074462461,34.6099995076656,0.291452071778149,0.044480080118968,1,-3.61119302201375E-7,,,,,,,,,,,,,,,,,,,,,99.999755859375,99.9999008178711,6800.3671875,6800.3671875,52.1928535573805,5.93262274667839,6.98959302902222,29,1,0,0,1,0.3424072265625,31.2805480957031,1,1,1,99.999755859375,0,742397376,99.9998283386231,,,,,,,,,,,,,,,,,,,,,,,,,,,,,,,,,
,3884634473.10479,130.001167297363,9300.4189453125,0.000155312026823056,8.48099760679949E-8,1,2,14.4053468704224,4.99982815242391,34.6300005912781,0.190873312337508,0.0294419145582867,1,1.1237892074028E-8,,,,,,,,,,,,,,,,,,,,,130.001129150391,130.001205444336,9300.4189453125,9300.4189453125,52.3448803043709,5.93310678726952,7.0457558631897,29,1,0,0,1,0.345535278320313,31.2805480957031,1,1,1,130.001205444336,0,742397472,130.001167297363,,,,,,,,,,,,,,,,,,,,,,,,,,,,,,,,,
,3884635103.56821,130.000411987305,3900.25,0.000138963329938071,4.40194473800177E-8,1,2,14.4053468704224,4.99971376851633,34.6300005912781,0.170766221968519,0.0264044636595402,1,6.09518817083531E-8,,,,,,,,,,,,,,,,,,,,,130.000305175781,130.000518798828,3900.25,3900.25,52.3288569197267,5.93238802598037,7.0506911277771,29,1,0,0,1,0.341949462890625,30.7917900085449,1,1,1,130.000305175781,0,742397568,130.000411987305,,,,,,,,,,,,,,,,,,,,,,,,,,,,,,,,,
,3884635797.87813,130.001113891602,-1500.32141113281,-0.000116260084371626,2.94699511345593E-8,1,2,14.4053468704224,4.99956392594,34.6300005912781,-0.142927099575948,-0.0216621834295082,1,2.96887232265785E-7,,,,,,,,,,,,,,,,,,,,,130.001007080078,130.001220703125,-1500.32141113281,-1500.32141113281,52.1068744202651,5.93267565879203,7.06565809249878,29,1,0,0,1,0.344161987304687,30.7917900085449,1,1,1,130.001007080078,0,742397664,130.001113891602,,,,,,,,,,,,,,,,,,,,,,,,,,,,,,,,,
,3884636417.41965,130.000663757324,-6900.2587890625,-0.000149496512818011,6.57386017809006E-8,1,2,14.4053468704224,4.99942129064892,34.6300005912781,-0.183776855509147,-0.0278728882739903,1,3.66277068687008E-7,,,,,,,,,,,,,,,,,,,,,130.000640869141,130.000686645508,-6900.2587890625,-6900.2587890625,52.3448803043709,5.93481520635476,7.07271766662598,29,1,0,0,1,0.340347290039063,30.7917900085449,1,1,1,130.000686645508,0,742397600,130.000663757324,,,,,,,,,,,,,,,,,,,,,,,,,,,,,,,,,
,3884637339.84667,130.002082824707,-9200.162109375,-0.000155006727416828,1.11549960034373E-7,1,2,14.4053468704224,4.99952836500328,34.6399992704391,-0.190478868813617,-0.0294031830065906,1,-2.87904941752337E-8,,,,,,,,,,,,,,,,,,,,,130.001876831055,130.002288818359,-9200.162109375,-9200.162109375,52.0615399661497,5.93414647466988,7.07695484161377,29,1,0,0,1,0.341796875,30.7917900085449,1,1,1,130.001876831055,0,742397312,130.002082824707,,,,,,,,,,,,,,,,,,,,,,,,,,,,,,,,,
,3884637967.35833,129.995727539062,-3800.43212890625,-0.000138415345519119,5.12297871132803E-8,1,2,14.4053468704224,4.99946794511394,34.6399992704391,-0.170066318939393,-0.0263949116234971,1,-1.39135600559459E-7,,,,,,,,,,,,,,,,,,,,,129.995574951172,129.995880126953,-3800.43212890625,-3800.43212890625,52.2108310133228,5.93388055628914,7.08108568191528,28,1,68,0,0,0.343017578125,30.3030319213867,1,1,1,129.995574951172,0,742397760,129.995727539062,,,,,,,,,,,,,,,,,,,,,,,,,,,,,,,,,
,3884638667.38297,130.000129699707,1600.31030273438,0.000118481889049264,2.92930459146729E-8,1,2,14.4053468704224,4.99939108942308,34.6399992704391,0.145640312631979,0.0221477484347626,1,-2.43439741101216E-7,,,,,,,,,,,,,,,,,,,,,130.000030517578,130.000228881836,1600.31030273438,1600.31030273438,52.123288619169,5.9346039453425,7.08734273910522,29,1,0,0,1,0.3411865234375,30.7917900085449,1,1,1,130.000228881836,0,742397472,130.000129699707,,,,,,,,,,,,,,,,,,,,,,,,,,,,,,,,,
,3884639274.21991,129.999557495117,7000.14990234375,0.000149389501799397,7.27794614565043E-8,1,2,14.4053468704224,4.99937652770537,34.6399992704391,0.183637862942205,0.0278860107651768,1,-3.38816905657145E-7,,,,,,,,,,,,,,,,,,,,,129.999526977539,129.999588012695,7000.14990234375,7000.14990234375,52.1834740151498,5.93447844194514,7.0847954750061,29,1,0,0,1,0.343399047851562,33.2355842590332,1,1,1,129.999526977539,0,742397632,129.999557495117,,,,,,,,,,,,,,,,,,,,,,,,,,,,,,,,,
,3884640379.45238,150.000289916992,9100.33203125,0.000108729199126829,9.05524194715664E-8,1,2,14.4053468704224,4.99940560372602,34.6500016748905,0.133599251598801,0.020671124973354,1,5.84580240821553E-8,,,,,,,,,,,,,,,,,,,,,150,150.000579833984,9100.33203125,9100.33203125,52.321431448794,5.93366705527216,7.11636924743652,29,1,0,0,1,0.341720581054687,30.7917900085449,1,1,1,150,0,742397344,150.000289916992,,,,,,,,,,,,,,,,,,,,,,,,,,,,,,,,,
,3884641011.55104,150.000679016113,3700.38208007812,0.000119054284053564,4.16125196352639E-8,1,2,14.4053468704224,4.99964329366738,34.6600003540516,0.146296509815947,0.0226304745472218,1,5.98511685182161E-8,,,,,,,,,,,,,,,,,,,,,150.000350952148,150.001007080078,3700.38208007812,3700.38208007812,52.2714072235632,5.93355082726001,7.12465715408325,29,1,0,0,1,0.34210205078125,29.8142719268799,1,1,1,150.000350952148,0,742397536,150.000679016113,,,,,,,,,,,,,,,,,,,,,,,,,,,,,,,,,
,3884641786.28241,150.001983642578,-1700.32360839844,-0.000111405812400225,2.74462148103784E-8,1,2,14.4053468704224,4.99969456531435,34.6500016748905,-0.13695747743689,-0.0208031733875117,1,2.48112006322631E-7,,,,,,,,,,,,,,,,,,,,,150.001983642578,150.001983642578,-1700.32360839844,-1700.32360839844,52.0748276509767,5.93344237545374,7.12468528747559,29,1,0,0,1,0.343399047851562,30.7917900085449,1,1,1,150.001983642578,0,742397536,150.001983642578,,,,,,,,,,,,,,,,,,,,,,,,,,,,,,,,,
,3884642400.64532,150.004859924316,-7100.4443359375,-0.00011337398042536,7.32259345701447E-8,1,2,14.4053468704224,4.99966825211463,34.6500016748905,-0.13940008295876,-0.0210145687606099,1,3.79412591255371E-7,,,,,,,,,,,,,,,,,,,,,150.004348754883,150.00537109375,-7100.4443359375,-7100.4443359375,52.4081922144286,5.93355406419358,7.13603353500366,29,1,0,0,1,0.340805053710937,31.7693061828613,1,1,1,150.004348754883,0,742397440,150.004859924316,,,,,,,,,,,,,,,,,,,,,,,,,,,,,,,,,
,3884643334.1893,150.000648498535,-9000.35546875,-0.000108781114941436,7.74262369184609E-8,1,2,14.4053468704224,4.99972862154777,34.6500016748905,-0.133664056343147,-0.0207543114122805,1,-1.16629241890934E-7,,,,,,,,,,,,,,,,,,,,,150.000564575195,150.000732421875,-9000.35546875,-9000.35546875,52.2080953135055,5.93349727019677,7.14134883880615,29,1,0,0,1,0.341644287109375,30.3030319213867,1,1,1,150.000732421875,0,742397504,150.000648498535,,,,,,,,,,,,,,,,,,,,,,,,,,,,,,,,,
,3884643960.59512,149.99747467041,-3600.21020507812,-0.000118846547363808,5.37534510670781E-8,1,2,14.4053468704224,4.99969058489154,34.6600003540516,-0.146032702731953,-0.022659129696298,1,-1.14953294909458E-7,,,,,,,,,,,,,,,,,,,,,149.99739074707,149.99755859375,-3600.21020507812,-3600.21020507812,52.2053596136882,5.9328977242601,7.13724088668823,29,1,0,0,1,0.343017578125,31.7693061828613,1,1,1,149.99739074707,0,742397312,149.99747467041,,,,,,,,,,,,,,,,,,,,,,,,,,,,,,,,,
,3884644637.40039,150.001564025879,1800.09301757813,0.000112545936407874,3.90383029896373E-8,1,2,14.4053468704224,4.99970381682923,34.6600003540516,0.138363012237496,0.0209930416369116,1,-2.69435711209734E-7,,,,,,,,,,,,,,,,,,,,,150.001449584961,150.001678466797,1800.09301757813,1800.09301757813,52.4476644546498,5.93340526065884,7.14417505264282,29,1,0,0,1,0.341644287109375,31.7693061828613,1,1,1,150.001449584961,0,742397472,150.001564025879,,,,,,,,,,,,,,,,,,,,,,,,,,,,,,,,,
,3884645247.16743,150.000267028809,7200.51806640625,0.000112711506584762,6.66437675839021E-8,1,2,14.4053468704224,4.99974487007727,34.6600003540516,0.138577098987128,0.0209661064331801,1,-3.17074992856007E-7,,,,,,,,,,,,,,,,,,,,,150.000061035156,150.000473022461,7200.51806640625,7200.51806640625,52.1502548030824,5.93338589566268,7.13998651504517,29,1,0,0,1,0.342788696289063,31.2805480957031,1,1,1,150.000061035156,0,742397440,150.000267028809,,,,,,,,,,,,,,,,,,,,,,,,,,,,,,,,,
,3884646341.87668,170.003211975098,8900.3662109375,8.15091064014868E-5,8.80050643321813E-8,1,2,14.4053468704224,4.99970783372124,34.6699990332127,0.100163622099305,0.0154832813270569,1,3.22828642787302E-8,,,,,,,,,,,,,,,,,,,,,170.003036499023,170.003387451172,8900.3662109375,8900.3662109375,52.1991065855344,5.93368959321708,7.16647720336914,29,1,0,0,1,0.340347290039063,30.7917900085449,1,1,1,170.003036499023,0,742397312,170.003211975098,,,,,,,,,,,,,,,,,,,,,,,,,,,,,,,,,
,3884646976.83238,169.995903015137,3500.23364257812,0.00010808063228051,3.47093349749273E-8,1,2,14.4053468704224,4.9997187406974,34.6699990332127,0.132815169712092,0.0205415286798928,1,5.15293292974847E-8,,,,,,,,,,,,,,,,,,,,,169.995681762695,169.996124267578,3500.23364257812,3500.23364257812,52.1877729720055,5.93314781526986,7.17452192306519,29,1,0,0,1,0.34210205078125,32.2580642700195,1,1,1,169.996124267578,0,742397536,169.995903015137,,,,,,,,,,,,,,,,,,,,,,,,,,,,,,,,,
,3884647750.91453,170.003341674805,-1900.14282226562,-0.000107775971680567,1.00912108022445E-7,1,2,14.4053468704224,4.99968282615478,34.680001437664,-0.132497993908901,-0.0201037699031171,1,2.5754367982668E-7,,,,,,,,,,,,,,,,,,,,,170.003158569336,170.003524780273,-1900.14282226562,-1900.14282226562,52.0912418498805,5.9337338006664,7.17465829849243,29,1,0,0,1,0.3460693359375,30.3030319213867,1,1,1,170.003158569336,0,742397440,170.003341674805,,,,,,,,,,,,,,,,,,,,,,,,,,,,,,,,,
,3884648369.90056,170.00074005127,-7300.31201171875,-8.99732243625531E-5,6.90081999560072E-8,1,2,14.4053468704224,4.99972565364501,34.680001437664,-0.110640514095107,-0.0166041343177434,1,3.60685222874156E-7,,,,,,,,,,,,,,,,,,,,,170.000640869141,170.000839233398,-7300.31201171875,-7300.31201171875,52.2624184955921,5.93380434224128,7.18655347824097,29,1,0,0,1,0.341110229492188,31.2805480957031,1,1,1,170.000839233398,0,742397152,170.00074005127,,,,,,,,,,,,,,,,,,,,,,,,,,,,,,,,,
,3884649271.7403,170.000038146973,-8800.42578125,-8.18980847999559E-5,7.76544071518039E-8,1,2,14.4053468704224,4.99964783477808,34.680001437664,-0.100618913435646,-0.0156933009984944,1,-1.43420914738947E-7,,,,,,,,,,,,,,,,,,,,,169.99983215332,170.000244140625,-8800.42578125,-8800.42578125,52.2753153661594,5.93399867129024,7.18652534484863,29,1,0,0,1,0.345993041992188,31.2805480957031,1,1,1,169.99983215332,0,742396800,170.000038146973,,,,,,,,,,,,,,,,,,,,,,,,,,,,,,,,,
,3884649891.83176,170.004249572754,-3400.47631835937,-0.000108336892684486,4.45144012714475E-8,1,2,14.4053468704224,4.999657117473,34.680001437664,-0.133114765803228,-0.0206743580034669,1,-1.20393585089402E-7,,,,,,,,,,,,,,,,,,,,,170.004150390625,170.004348754883,-3400.47631835937,-3400.47631835937,52.1901178575632,5.93407071049345,7.18771028518677,29,1,0,0,1,0.340194702148438,32.2580642700195,1,1,1,170.004348754883,0,742397568,170.004249572754,,,,,,,,,,,,,,,,,,,,,,,,,,,,,,,,,
,3884650559.4651,170.000839233398,2000.14392089844,0.000108273173100051,4.55044837474232E-8,1,2,14.4053468704224,4.99962200655224,34.680001437664,0.133097263644649,0.0202592555173646,1,-2.07398982975185E-7,,,,,,,,,,,,,,,,,,,,,170.000793457031,170.000885009766,2000.14392089844,2000.14392089844,52.2835224656113,5.93506231025718,7.19710350036621,29,1,0,0,1,0.340194702148438,31.2805480957031,1,1,1,170.000885009766,0,742397600,170.000839233398,,,,,,,,,,,,,,,,,,,,,,,,,,,,,,,,,
,3884651167.42335,170.002349853516,7400.44677734375,8.94172558143464E-5,6.6773861271619E-8,1,2,14.4053468704224,4.99967564212411,34.680001437664,0.109945468723988,0.0165651008546811,1,-3.06543051851734E-7,,,,,,,,,,,,,,,,,,,,,170.002288818359,170.002410888672,7400.44677734375,7400.44677734375,52.2823500228325,5.93473882204743,7.19561767578125,29,1,0,0,1,0.341567993164063,31.7693061828613,1,1,1,170.002288818359,0,742397440,170.002349853516,,,,,,,,,,,,,,,,,,,,,,,,,,,,,,,,,
,3884652266.80422,200.000411987305,8700.291015625,5.79790325784177E-5,8.22947647254003E-8,1,2,14.4053468704224,4.99968165371206,34.7100012004375,0.0712434306285165,0.0110420647635598,1,4.62212021652013E-8,,,,,,,,,,,,,,,,,,,,,200.000366210938,200.000457763672,8700.291015625,8700.291015625,52.3378456476978,5.93471449194406,7.24866580963135,29,1,0,0,1,0.345840454101562,32.7468223571777,1,1,1,200.000457763672,0,742397600,200.000411987305,,,,,,,,,,,,,,,,,,,,,,,,,,,,,,,,,
,3884652895.35866,200.001487731934,3300.26806640625,9.91578852491494E-5,3.22370408195608E-8,1,2,14.4053468704224,4.99970337589362,34.7100012004375,0.121848797009215,0.0188528123786718,1,5.31330494335646E-8,,,,,,,,,,,,,,,,,,,,,200.001480102539,200.001495361328,3300.26806640625,3300.26806640625,52.3210406345344,5.93414952410772,7.25451135635376,29,1,0,0,1,0.344390869140625,28.3479976654053,1,1,1,200.001480102539,0,742397408,200.001487731934,,,,,,,,,,,,,,,,,,,,,,,,,,,,,,,,,
,3884653689.48765,199.999649047852,-2100.12060546875,-0.000102607356481419,3.10965181336364E-8,1,2,14.4053468704224,4.99971109023504,34.7100012004375,-0.126143169533,-0.0191502323947355,1,2.36706634362997E-7,,,,,,,,,,,,,,,,,,,,,199.999465942383,199.99983215332,-2100.12060546875,-2100.12060546875,52.1869913434863,5.93473573755714,7.26113843917847,29,1,0,0,1,0.3424072265625,31.2805480957031,1,1,1,199.999465942383,0,742397472,199.999649047852,,,,,,,,,,,,,,,,,,,,,,,,,,,,,,,,,
,3884654303.49305,200.000289916992,-7500.326171875,-6.76791004969196E-5,6.61285934014274E-8,1,2,14.4053468704224,4.99972453480705,34.7100012004375,-0.0832468365115722,-0.0123501331531026,1,3.85004906834429E-7,,,,,,,,,,,,,,,,,,,,,200.000076293945,200.000503540039,-7500.326171875,-7500.326171875,52.1889454147844,5.93436811201553,7.27841949462891,29,1,0,0,1,0.346908569335937,32.7468223571777,1,1,1,200.000076293945,0,742397344,200.000289916992,,,,,,,,,,,,,,,,,,,,,,,,,,,,,,,,,
,3884655193.76717,200.00479888916,-8600.423828125,-5.87879258413209E-5,8.20553731652817E-8,1,2,14.4053468704224,4.99970370885886,34.7199998795986,-0.0722240912220834,-0.0112852711418247,1,-1.19355030723087E-7,,,,,,,,,,,,,,,,,,,,,200.004486083984,200.005111694336,-8600.423828125,-8600.423828125,52.2131758988805,5.93545462058605,7.30743408203125,29,1,0,0,1,0.34027099609375,32.7468223571777,1,1,1,200.004486083984,0,742397696,200.00479888916,,,,,,,,,,,,,,,,,,,,,,,,,,,,,,,,,
,3884655816.67451,199.999923706055,-3200.38891601562,-9.9644611430322E-5,4.51192585488957E-8,1,2,14.4053468704224,4.99964437705878,34.7199998795986,-0.122445437480244,-0.0189414969819041,1,-5.05093316530889E-8,,,,,,,,,,,,,,,,,,,,,199.999588012695,200.000259399414,-3200.38891601562,-3200.38891601562,52.2592919815151,5.93488594772612,7.32103872299194,29,1,0,0,1,0.342330932617188,31.7693061828613,1,1,1,199.999588012695,0,742397344,199.999923706055,,,,,,,,,,,,,,,,,,,,,,,,,,,,,,,,,
,3884656525.54416,199.995933532715,2200.19482421875,0.000102583326349807,3.17667122811848E-8,1,2,14.4053468704224,4.99963582687432,34.7199998795986,0.126102161669723,0.0192025617846918,1,-1.90093236733351E-7,,,,,,,,,,,,,,,,,,,,,199.995742797852,199.996124267578,2200.19482421875,2200.19482421875,52.250303253544,5.9347361211559,7.33858489990234,29,1,0,0,1,0.34698486328125,32.2580642700195,1,1,1,199.995742797852,0,742397632,199.995933532715,,,,,,,,,,,,,,,,,,,,,,,,,,,,,,,,,
,3884657146.11814,200.001205444336,7600.24169921875,6.67937722299606E-5,6.9900598979801E-8,1,2,14.4053468704224,4.99963284078053,34.7199998795986,0.0821353814861965,0.0123204683528352,1,-2.7239227123613E-7,,,,,,,,,,,,,,,,,,,,,200.001174926758,200.001235961914,7600.24169921875,7600.24169921875,52.1338406041786,5.93498828198242,7.34133863449097,29,1,0,0,1,0.344390869140625,31.2805480957031,1,1,1,200.001235961914,0,742397088,200.001205444336,,,,,,,,,,,,,,,,,,,,,,,,,,,,,,,,,
,3884658324.93194,250.001571655273,8500.3623046875,3.5634357290256E-5,7.93531612703799E-8,1,2,14.4053468704224,4.99963665887068,34.7799994051456,0.0437691212195805,0.00689728624152427,1,1.18596237435992E-7,,,,,,,,,,,,,,,,,,,,,250.001434326172,250.001708984375,8500.3623046875,8500.3623046875,52.1311049043613,5.93588474954994,7.72560691833496,29,1,0,0,1,0.342788696289063,29.8142719268799,1,1,1,250.001434326172,0,742397376,250.001571655273,,,,,,,,,,,,,,,,,,,,,,,,,,,,,,,,,
,3884659014.2745,250.001678466797,3100.31469726562,9.11357145241631E-5,3.44524743650747E-8,1,2,14.4053468704224,4.99961944996959,34.7799994051456,0.112010358656929,0.017183723119946,1,-6.78828767022938E-8,,,,,,,,,,,,,,,,,,,,,250.001678466797,250.001678466797,3100.31469726562,3100.31469726562,52.2256819551882,5.93499187361696,7.78527641296387,29,1,0,0,1,0.34271240234375,32.7468223571777,1,1,1,250.001678466797,0,742397664,250.001678466797,,,,,,,,,,,,,,,,,,,,,,,,,,,,,,,,,
,3884659825.36259,249.999481201172,-2300.08618164062,-9.54684393973719E-5,3.75650301835315E-8,1,2,14.4053468704224,4.99954520998709,34.7799994051456,-0.117371596278506,-0.0177503859677373,1,2.74468762019226E-7,,,,,,,,,,,,,,,,,,,,,249.998977661133,249.999984741211,-2300.08618164062,-2300.08618164062,52.1815199438517,5.93515792509439,7.95441341400146,29,1,0,0,1,0.346755981445313,31.2805480957031,1,1,1,249.998977661133,0,742397472,249.999481201172,,,,,,,,,,,,,,,,,,,,,,,,,,,,,,,,,
,3884660431.782,250.003082275391,-7700.4140625,-4.40569726369108E-5,7.15750811732709E-8,1,2,14.4053468704224,4.99949166188943,34.7799994051456,-0.0541917067157867,-0.00801216193261275,1,2.72488521530838E-7,,,,,,,,,,,,,,,,,,,,,250.002853393555,250.003311157227,-7700.4140625,-7700.4140625,52.240142082794,5.93564958097682,8.1350793838501,29,1,0,0,1,0.343780517578125,32.7468223571777,1,1,1,250.002853393555,0,742397504,250.003082275391,,,,,,,,,,,,,,,,,,,,,,,,,,,,,,,,,
,3884661328.61262,250.00129699707,-8400.2265625,-3.66235564803178E-5,7.50715093796251E-8,1,2,14.4053468704224,4.99927538509317,34.7799994051456,-0.0449785295564677,-0.00709505312864685,1,-1.2759634066388E-7,,,,,,,,,,,,,,,,,,,,,250.000991821289,250.001602172852,-8400.2265625,-8400.2265625,52.2284176550055,5.93691070579865,8.38011646270752,29,1,0,0,1,0.340499877929687,29.8142719268799,1,1,1,250.001602172852,0,742397536,250.00129699707,,,,,,,,,,,,,,,,,,,,,,,,,,,,,,,,,
,3884661953.99784,249.999504089355,-3000.21606445313,-9.16573286121051E-5,4.62429306109178E-8,1,2,14.4053468704224,4.99921694897775,34.7799994051456,-0.112606407416495,-0.0174903353188009,1,-1.02793437234793E-7,,,,,,,,,,,,,,,,,,,,,249.999465942383,249.999542236328,-3000.21606445313,-3000.21606445313,52.1174264052747,5.93755040451153,8.4988431930542,29,1,0,0,1,0.342559814453125,31.2805480957031,1,1,1,249.999465942383,0,742397472,249.999504089355,,,,,,,,,,,,,,,,,,,,,,,,,,,,,,,,,
,3884662669.91156,250.000923156738,2400.20947265625,9.5023202728824E-5,3.07017955031379E-8,1,2,14.4053468704224,4.99925728762683,34.7799994051456,0.116806739116999,0.0177187132632272,1,-2.3044140783882E-7,,,,,,,,,,,,,,,,,,,,,250.000854492187,250.000991821289,2400.20947265625,2400.20947265625,52.377317887919,5.93681826536982,8.58725357055664,29,1,0,0,1,0.339126586914063,30.3030319213867,1,1,1,250.000991821289,0,742397024,250.000923156738,,,,,,,,,,,,,,,,,,,,,,,,,,,,,,,,,
,3884663282.77695,250.000473022461,7800.439453125,4.28691497230091E-5,7.95477881535546E-8,1,2,14.4053468704224,4.99905316614525,34.7799994051456,0.052733650687151,0.00773387974900911,1,-3.15042201859558E-7,,,,,,,,,,,,,,,,,,,,,250.000366210938,250.000579833984,7800.439453125,7800.439453125,52.2123942703613,5.93746403296685,8.62090682983398,29,1,0,0,1,0.338363647460937,31.2805480957031,1,1,1,250.000366210938,0,742397536,250.000473022461,,,,,,,,,,,,,,,,,,,,,,,,,,,,,,,,,
,3884664451.60626,300.000091552734,8300.322265625,2.34871347931081E-5,6.19796411460554E-8,1,2,14.4053468704224,4.99896314387966,34.8699986934662,0.0288351880574423,0.00459893531326729,1,1.21861229883429E-7,,,,,,,,,,,,,,,,,,,,,299.999664306641,300.000518798828,8300.322265625,8300.322265625,52.2987642217363,5.93863801223572,10.331748008728,29,1,0,0,1,0.342788696289063,31.7693061828613,1,1,1,299.999664306641,0,742397632,300.000091552734,,,,,,,,,,,,,,,,,,,,,,,,,,,,,,,,,
,3884665113.22885,300.000717163086,2900.1416015625,8.69939498538036E-5,3.40645375271586E-8,1,2,14.4053468704224,4.99892128203597,34.8699986934662,0.106874235771882,0.0165610214116497,1,6.65821883082062E-8,,,,,,,,,,,,,,,,,,,,,300.000366210937,300.001068115234,2900.1416015625,2900.1416015625,52.2295900977844,5.93904371201112,10.6748580932617,29,1,0,0,1,0.343170166015625,33.7243423461914,1,1,1,300.000366210937,0,742397600,300.000717163086,,,,,,,,,,,,,,,,,,,,,,,,,,,,,,,,,
,3884665828.30053,300.000503540039,-2500.06396484375,-8.97199138895699E-5,4.79485759189012E-8,1,2,14.4053468704224,4.99893569167704,34.8699986934662,-0.110288188775816,-0.0166610537529434,1,2.72330943399506E-7,,,,,,,,,,,,,,,,,,,,,300.000427246094,300.000579833984,-2500.06396484375,-2500.06396484375,52.2616368670728,5.93925799971358,10.4574518203735,29,1,0,0,1,0.338287353515625,31.7693061828613,1,1,1,300.000579833984,0,742397312,300.000503540039,,,,,,,,,,,,,,,,,,,,,,,,,,,,,,,,,
,3884666465.23268,300.004318237305,-7900.3916015625,-2.80001791536621E-5,7.55925382050077E-8,1,2,14.4053468704224,4.99884433864696,34.8699986934662,-0.0344587943832789,-0.0049371220908528,1,2.98558518430692E-7,,,,,,,,,,,,,,,,,,,,,300.004272460937,300.004364013672,-7900.3916015625,-7900.3916015625,52.2698439665248,5.9391759809525,10.331693649292,29,1,0,0,1,0.339202880859375,31.2805480957031,1,1,1,300.004364013672,0,742397696,300.004318237305,,,,,,,,,,,,,,,,,,,,,,,,,,,,,,,,,
,3884667395.74495,300.00032043457,-8200.37109375,-2.45296601417145E-5,7.81104372309545E-8,1,2,14.4053468704224,4.99879426446758,34.8699986934662,-0.0301216397205572,-0.00475121779108935,1,-8.52520069936674E-8,,,,,,,,,,,,,,,,,,,,,300.000030517578,300.000610351562,-8200.37109375,-8200.37109375,52.2932928221017,5.93941633619565,10.2105178833008,29,1,0,0,1,0.340042114257812,31.7693061828613,1,1,1,300.000610351562,0,742397664,300.00032043457,,,,,,,,,,,,,,,,,,,,,,,,,,,,,,,,,
,3884668023.67644,299.999862670898,-2800.32348632813,-8.78819796104508E-5,4.35001838649346E-8,1,2,14.4053468704224,4.99877983099134,34.8699986934662,-0.10795030896967,-0.016798411269397,1,-1.23418561179079E-7,,,,,,,,,,,,,,,,,,,,,299.999694824219,300.000030517578,-2800.32348632813,-2800.32348632813,52.2592919815151,5.93978041827566,10.1532564163208,29,1,0,0,1,0.339202880859375,31.7693061828613,1,1,1,299.999694824219,0,742397696,299.999862670898,,,,,,,,,,,,,,,,,,,,,,,,,,,,,,,,,
,3884668733.14999,300.001968383789,2600.296875,8.8969619700844E-5,5.50889081835754E-8,1,2,14.4053468704224,4.99864867300718,34.8699986934662,0.109348367083655,0.0165773142823586,1,-2.23729772187996E-7,,,,,,,,,,,,,,,,,,,,,300.001403808594,300.002532958984,2600.296875,2600.296875,52.2632001241113,5.93953843413373,10.1036710739136,29,1,0,0,1,0.337905883789063,31.2805480957031,1,1,1,300.001403808594,0,742397536,300.001968383789,,,,,,,,,,,,,,,,,,,,,,,,,,,,,,,,,
,3884669354.3679,300.000747680664,8000.44189453125,2.66717490815931E-5,7.45168033896011E-8,1,2,14.4053468704224,4.99875550071566,34.8699986934662,0.0328190778139805,0.0047290633743353,1,-2.62993506259747E-7,,,,,,,,,,,,,,,,,,,,,300.000701904297,300.000793457031,8000.44189453125,8000.44189453125,52.2674990809671,5.93926542671262,10.0722093582153,29,1,0,0,1,0.338211059570313,29.8142719268799,1,1,1,300.000701904297,0,742397664,300.000747680664,,,,,,,,,,,,,,,,,,,,,,,,,,,,,,,,,
,3884669807.66721,300.002365112305,70000.296875,-0.000780627034813672,1.26834123705287E-6,1,2,14.4053468704224,4.99879495272234,34.8699986934662,-0.95914282749763,-0.147585411275519,1,2.30430172280882E-7,,,,,,,,,,,,,,,,,,,,,300.001647949219,300.003082275391,70000.296875,70000.296875,51.8954439058132,5.9392808888332,10.0480403900146,28,1,64,0,0,0.343780517578125,31.2805480957031,1,1,1,300.001495361328,0,742397408,300.002365112305,,,,,,,,,,,,,,,,,,,,,,,,,,,,,,,,,