File: S16-M-T_H.dat
[Header]
; MPMS3 Data File (default extension .dat)
; Copyright (c) 2007, Quantum Design, Inc. All rights reserved.
TITLE,
FILEOPENTIME,3884671344.65497,02/04/2023,11:22 am
BYAPP,MPMS3 w/ AC,1.0,1.1
INFO,MPMS3 Measurement Release 1.1.16 Build 424, MultiVu Release 2.3.4.19,APPNAME
INFO,Linear Motor Servo Controller,MOTOR_MODULE_NAME
INFO,3101-100 N0,MOTOR_HW_VERSION
INFO,MMC1038,MOTOR_SERIAL_NUMBER
INFO,01.04.28,MOTOR_SOFTWARE_VERSION
INFO,Quantum Design Squid Module,SQUID_MODULE_NAME
INFO,3101-501 B0,SQUID_HW_VERSION
INFO,SQM266,SQUID_SERIAL_NUMBER
INFO,01.03.04,SQUID_SOFTWARE_VERSION
INFO,SQUID AC,AC_MODULE_NAME
INFO,3101-401 G0,AC_HW_VERSION
INFO,SAC261,AC_SERIAL_NUMBER
INFO,SQUID AC 00.95.07,AC_SOFTWARE_VERSION
INFO,TCI280,COIL_SERIAL_NUMBER
INFO,0,MOMENT_UNITS
INFO,Nb-Y-[Ho8-Er6]_10-TaN,SAMPLE_MATERIAL
INFO,,SAMPLE_COMMENT
INFO,,SAMPLE_MASS
INFO,,SAMPLE_VOLUME
INFO,,SAMPLE_MOLECULAR_WEIGHT
INFO,,SAMPLE_SIZE
INFO,,SAMPLE_SHAPE
INFO,Quartz,SAMPLE_HOLDER
INFO,Standard,SAMPLE_HOLDER_DETAIL
INFO,63.69,SAMPLE_OFFSET
DATATYPE,COMMENT,1
DATATYPE,TIME,2
STARTUPAXIS,X,2
STARTUPAXIS,Y1,5
FIELDGROUP, VSM,2,3,4,5,6,8,9,10,11,14,15
FIELDGROUP, DC, 2,3,4,14,56,57,58,59,60,61,62,63,64,65,66,67,68,69
FIELDGROUP, AC, 2,3,4,11,16,17,18,19,20,21,22,23,24,25,26,27,28,29,30
STARTUPGROUP, All
[Data]
Comment,Time Stamp (sec),Temperature (K),Magnetic Field (Oe),Moment (emu),M. Std. Err. (emu),Transport Action,Averaging Time (sec),Frequency (Hz),Peak Amplitude (mm),Center Position (mm),Lockin Signal' (V),Lockin Signal (V),Range,M. Quad. Signal (emu),AC Moment (emu),AC M. Std Err. (emu),AC Phase (deg),AC Phase Std. Err. (deg),AC Susceptibility (emu/Oe),AC Suscept. Std Err. (emu/Oe),AC X' (emu/Oe),AC X' Std Err. (emu/Oe),AC X'' (emu/Oe),AC X'' Std Err. (emu/Oe),AC Drive (Oe),AC Frequency (Hz),AC Averaging Time (sec),AC Cycles,AC Range,AC Measure Type,AC Signal' (V),AC Signal'' (V),AC Trim Coil Ratio,AC Trim Coil Phase,Min. Temperature (K),Max. Temperature (K),Min. Field (Oe),Max. Field (Oe),Mass (grams),Motor Lag (deg),Pressure (Torr),Measure Count,Measurement Number,SQUID Status (code),Motor Status (code),Measure Status (code),Motor Current (amps),Motor Temp. (C),Temp. Status (code),Field Status (code),Chamber Status (code),Chamber Temp (K),Redirection State,Evercool Status,Average Temp (K),Rotation Angle (deg),Rotator state,DC Moment Fixed Ctr (emu),DC Moment Err Fixed Ctr (emu),DC Moment Free Ctr (emu),DC Moment Err Free Ctr (emu),DC Fixed Fit,DC Free Fit,DC Calculated Center (mm),DC Calculated Center Err (mm),DC Scan Length (mm),DC Scan Time (s),DC Number of Points,DC Squid Drift,DC Min V (V),DC Max V (V),DC Scans per Measure,Map 01,Map 02,Map 03,Map 04,Map 05,Map 06,Map 07,Map 08,Map 09,Map 10,Map 11,Map 12,Map 13,Map 14,Map 15,Map 16
,3884674049.02552,1.9998607635498,9.63425254821777,7.47398727989259E-6,2.18851696700586E-8,1,3,14.4053468704224,4.97859948625666,34.5799997448921,0.00913988377663988,0.00135024238068323,1,-4.70867619147638E-8,,,,,,,,,,,,,,,,,,,,,1.9998607635498,1.9998607635498,9.63425254821777,9.63425254821777,51.9446865025247,5.93309304644541,2.771897315979,43,1,0,0,1,0.340652465820313,27.8592376708984,1,1,1,1.9998607635498,0,742397568,1.9998607635498,,,,,,,,,,,,,,,,,,,,,,,,,,,,,,,,,
,3884676055.05278,56.6205005645752,9.63425254821777,3.87790773761721E-6,5.74750349815168E-9,1,3,14.4053468704224,4.97883268148406,34.5899984240532,0.00474133351897188,0.000708677674682429,1,-1.78397860978921E-8,,,,,,,,,,,,,,,,,,,,,56.6191673278809,56.6218338012695,9.63425254821777,9.63425254821777,52.1998882140536,5.93359342590311,6.77388334274292,43,1,0,0,1,0.337753295898438,30.3030319213867,1,1,1,56.6218338012695,0,742397536,56.6205005645752,,,,,,,,,,,,,,,,,,,,,,,,,,,,,,,,,
,3884678100.39853,111.200210571289,9.63425254821777,3.21606834558358E-6,6.41353714009783E-9,1,3,14.4053468704224,4.9787811333075,34.6199981868267,0.00393075370306048,0.000596303167617435,1,-7.7696560388805E-9,,,,,,,,,,,,,,,,,,,,,111.197570800781,111.202850341797,9.63425254821777,9.63425254821777,52.0701378798613,5.93388403581041,7.09270906448364,43,1,0,0,1,0.341415405273438,30.7917900085449,1,1,1,111.202850341797,0,742397536,111.200210571289,,,,,,,,,,,,,,,,,,,,,,,,,,,,,,,,,
,3884680143.70464,165.818359375,9.63425254821777,2.94445275539489E-6,6.19198323781585E-9,1,3,14.4053468704224,4.97873325519663,34.6699990332127,0.00359832714492628,0.000548550368787399,1,-4.97244558207647E-9,,,,,,,,,,,,,,,,,,,,,165.812744140625,165.823974609375,9.63425254821777,9.63425254821777,52.1959800714574,5.93521781373922,7.26784610748291,43,1,0,0,1,0.342636108398438,31.7693061828613,1,1,1,165.823974609375,0,742397344,165.818359375,,,,,,,,,,,,,,,,,,,,,,,,,,,,,,,,,
,3884682201.08624,220.44556427002,9.63425254821777,2.87317566564842E-6,6.9004684235523E-9,1,3,14.4053468704224,4.97856045246317,34.7400009632111,0.00351240300943739,0.000526477748436461,1,-1.20288112508588E-8,,,,,,,,,,,,,,,,,,,,,220.441543579102,220.449584960938,9.63425254821777,9.63425254821777,52.1354038612171,5.93572456261341,7.50244951248169,43,1,0,0,1,0.343093872070313,31.7693061828613,1,1,1,220.449584960938,0,742397440,220.44556427002,,,,,,,,,,,,,,,,,,,,,,,,,,,,,,,,,
,3884684272.91572,275.073715209961,9.63425254821777,2.81703288866568E-6,6.16157846224909E-9,1,3,14.4053468704224,4.97832389239485,34.8200015723705,0.00344198308478727,0.000526259762947375,1,-3.52285522862527E-9,,,,,,,,,,,,,,,,,,,,,275.069946289062,275.077484130859,9.63425254821777,9.63425254821777,52.1228978049094,5.93617867331891,9.18253040313721,43,1,0,0,1,0.3399658203125,32.2580642700195,1,1,1,275.077484130859,0,742397664,275.073715209961,,,,,,,,,,,,,,,,,,,,,,,,,,,,,,,,,
,3884689734.11778,26.8334712982178,10.3537721633911,0.000174081336568083,3.1491866701276E-8,1,3,14.4053468704224,4.97877100721208,34.5799997448921,0.212709884181078,0.0326387646615692,1,-1.24440137755359E-7,,,,,,,,,,,,,,,,,,,,,26.8334712982178,26.8334712982178,10.3537721633911,10.3537721633911,52.2561654674382,5.93525747195201,6.13071203231812,43,1,0,0,1,0.337448120117188,32.7468223571777,1,1,1,26.8334712982178,0,742397664,26.8334712982178,,,,,,,,,,,,,,,,,,,,,,,,,,,,,,,,,
,3884691752.4578,81.4252548217773,10.3537721633911,-1.16038384948779E-6,6.30366336411063E-9,1,3,14.4053468704224,4.97860956258745,34.6000008285046,-0.00141819052277459,-0.000215071749982731,1,2.85980497315063E-9,,,,,,,,,,,,,,,,,,,,,81.4219284057617,81.428581237793,10.3537721633911,10.3537721633911,52.2037963566498,5.93574786939324,6.93104696273804,43,1,0,0,1,0.337905883789063,31.7693061828613,1,1,1,81.428581237793,0,742397536,81.4252548217773,,,,,,,,,,,,,,,,,,,,,,,,,,,,,,,,,
,3884693793.84854,136.028015136719,10.3537721633911,-1.02842088587878E-7,7.12885281398554E-9,1,3,14.4053468704224,4.97845214596803,34.6399992704391,-0.000125374286277305,-2.10779599188477E-5,1,-1.39798937492103E-9,,,,,,,,,,,,,,,,,,,,,136.022430419922,136.033599853516,10.3537721633911,10.3537721633911,52.1228978049094,5.93694936040754,7.16181898117065,43,1,0,0,1,0.339202880859375,33.7243423461914,1,1,1,136.033599853516,0,742397440,136.028015136719,,,,,,,,,,,,,,,,,,,,,,,,,,,,,,,,,
,3884695842.17632,190.65022277832,10.3537721633911,-2.57739674659668E-7,6.766669050436E-9,1,3,14.4053468704224,4.97842012624846,34.6999987959862,-0.000315797689448415,-4.25027747518736E-5,1,4.94541066330625E-9,,,,,,,,,,,,,,,,,,,,,190.645614624023,190.654830932617,10.3537721633911,10.3537721633911,52.2030147281305,5.93664215335954,7.33164644241333,43,1,0,0,1,0.338668823242188,31.7693061828613,1,1,1,190.654830932617,0,742397600,190.65022277832,,,,,,,,,,,,,,,,,,,,,,,,,,,,,,,,,
,3884697910.91004,245.278709411621,10.3537721633911,-4.60897979480115E-7,6.916510193321E-9,1,3,14.4053468704224,4.97816063013795,34.7700007259846,-0.000565058353344089,-7.35319391231725E-5,1,1.08633264863945E-8,,,,,,,,,,,,,,,,,,,,,245.274383544922,245.28303527832,10.3537721633911,10.3537721633911,52.099839763592,5.93726378588857,7.80209684371948,43,1,0,0,1,0.33599853515625,31.7693061828613,1,1,1,245.28303527832,0,742397664,245.278709411621,,,,,,,,,,,,,,,,,,,,,,,,,,,,,,,,,
,3884699990.64884,299.908874511719,10.3537721633911,-5.88873495063645E-7,7.2831374481788E-9,1,3,14.4053468704224,4.97808041826169,34.8699986934662,-0.000720278874140266,-0.000104717317928189,1,5.06270474548219E-9,,,,,,,,,,,,,,,,,,,,,299.903015136719,299.914733886719,10.3537721633911,10.3537721633911,52.1576802740151,5.93830817160387,10.3528547286987,43,1,0,0,1,0.339431762695313,31.7693061828613,1,1,1,299.914733886719,0,742397344,299.908874511719,,,,,,,,,,,,,,,,,,,,,,,,,,,,,,,,,
,3884704469.38638,51.6584053039551,49.7078628540039,1.16159280785948E-5,6.11075346534682E-9,1,3,14.4053468704224,4.97856824764547,34.5899984240532,0.0141986732346159,0.00213894209755973,1,-4.00801131960498E-8,,,,,,,,,,,,,,,,,,,,,51.6576843261719,51.6591262817383,49.7078628540039,49.7078628540039,52.1936351858998,5.9352607517695,6.6911039352417,43,1,0,0,1,0.3424072265625,30.3030319213867,1,1,1,51.6591262817383,0,742397600,51.6584053039551,,,,,,,,,,,,,,,,,,,,,,,,,,,,,,,,,
,3884706513.7431,106.236946105957,49.7078628540039,9.00561379303675E-6,6.08081761862253E-9,1,3,14.4053468704224,4.97841998093463,34.6199981868267,0.0110065154660958,0.00166466449197436,1,-2.57925054897104E-8,,,,,,,,,,,,,,,,,,,,,106.233467102051,106.240425109863,49.7078628540039,49.7078628540039,52.1983249570151,5.93614851772414,7.06349468231201,43,1,0,0,1,0.341262817382812,31.7693061828613,1,1,1,106.240425109863,0,742397664,106.236946105957,,,,,,,,,,,,,,,,,,,,,,,,,,,,,,,,,
,3884708554.66219,160.854362487793,49.7078628540039,7.34815464472538E-6,6.81436534173343E-9,1,3,14.4053468704224,4.97840165660722,34.6600003540516,0.00898255179632467,0.00134659056288299,1,-3.06144936410631E-8,,,,,,,,,,,,,,,,,,,,,160.849212646484,160.859512329102,49.7078628540039,49.7078628540039,52.1619792308709,5.93618975685983,7.23648691177368,43,1,0,0,1,0.341567993164063,31.7693061828613,1,1,1,160.859512329102,0,742397632,160.854362487793,,,,,,,,,,,,,,,,,,,,,,,,,,,,,,,,,
,3884710620.39328,215.48136138916,49.7078628540039,7.13447629615554E-6,6.91977883498573E-9,1,3,14.4053468704224,4.97833030200635,34.7299985587597,0.00871995711729233,0.00131528531419404,1,-2.3274831032192E-8,,,,,,,,,,,,,,,,,,,,,215.476776123047,215.485946655273,49.7078628540039,49.7078628540039,52.1389211895536,5.93667585652231,7.4333119392395,43,1,0,0,1,0.340042114257812,29.8142719268799,1,1,1,215.485946655273,0,742397728,215.48136138916,,,,,,,,,,,,,,,,,,,,,,,,,,,,,,,,,
,3884712686.17518,270.107147216797,49.7078628540039,7.03971502108196E-6,8.02920758284088E-9,1,3,14.4053468704224,4.9780284181311,34.8099991679192,0.00860254672541831,0.00130329200867304,1,-1.83922383812727E-8,,,,,,,,,,,,,,,,,,,,,270.103363037109,270.110931396484,49.7078628540039,49.7078628540039,52.1897270433036,5.93817730009613,8.77710723876953,43,1,0,0,1,0.339508056640625,29.8142719268799,1,1,1,270.110931396484,0,742397312,270.107147216797,,,,,,,,,,,,,,,,,,,,,,,,,,,,,,,,,
,3884718160.41546,21.8666925430298,50.3786010742188,0.000598015312536997,4.72730648787422E-8,1,3,14.4053468704224,4.978528401888,34.5799997448921,0.730789741708458,0.111304761120297,10,-1.09080815801252E-6,,,,,,,,,,,,,,,,,,,,,21.8662700653076,21.867115020752,50.3786010742188,50.3786010742188,52.2014514710921,5.93626291809412,5.92815828323364,43,1,0,0,1,0.33843994140625,31.2805480957031,1,1,1,21.8662700653076,0,742397440,21.8666925430298,,,,,,,,,,,,,,,,,,,,,,,,,,,,,,,,,
,3884720171.85668,76.4632759094238,50.3786010742188,8.27499134382375E-6,6.37529494668948E-9,1,3,14.4053468704224,4.97842036709353,34.6000008285046,0.0101120417361599,0.00153946923692258,1,-1.56303086689008E-8,,,,,,,,,,,,,,,,,,,,,76.4599533081055,76.4665985107422,50.3786010742188,50.3786010742188,52.2108310133228,5.93672186782408,6.92013692855835,43,1,0,0,1,0.334548950195313,32.2580642700195,1,1,1,76.4665985107422,0,742397248,76.4632759094238,,,,,,,,,,,,,,,,,,,,,,,,,,,,,,,,,
,3884722211.19857,131.058662414551,50.3786010742188,5.71675348471698E-6,6.48049654024777E-9,1,3,14.4053468704224,4.97822596539462,34.6300005912781,0.00698534211223239,0.00106445915319278,1,-9.99641071238202E-9,,,,,,,,,,,,,,,,,,,,,131.054351806641,131.062973022461,50.3786010742188,50.3786010742188,52.1846464579286,5.93738490898416,7.15206050872803,43,1,0,0,1,0.340118408203125,31.7693061828613,1,1,1,131.062973022461,0,742397728,131.058662414551,,,,,,,,,,,,,,,,,,,,,,,,,,,,,,,,,
,3884724258.47213,185.684455871582,50.3786010742188,5.18122686689008E-6,6.92115850688259E-9,1,3,14.4053468704224,4.97831258402063,34.6900001168251,0.00633074689530011,0.00096726705954852,1,-7.01393017982873E-9,,,,,,,,,,,,,,,,,,,,,185.679443359375,185.689468383789,50.3786010742188,50.3786010742188,52.2178656699959,5.93625358862636,7.31953811645508,43,1,0,0,1,0.338821411132812,29.8142719268799,1,1,1,185.689468383789,0,742397600,185.684455871582,,,,,,,,,,,,,,,,,,,,,,,,,,,,,,,,,
,3884726327.28101,240.312812805176,50.3786010742188,4.82540613586463E-6,7.69697552905743E-9,1,3,14.4053468704224,4.9780817660162,34.7599983215332,0.00589849067420522,0.000882037584517821,1,-2.18769921275436E-8,,,,,,,,,,,,,,,,,,,,,240.30793762207,240.317687988281,50.3786010742188,50.3786010742188,52.1674506305055,5.93819206336513,7.71421241760254,43,1,0,0,1,0.33538818359375,31.7693061828613,1,1,1,240.317687988281,0,742397600,240.312812805176,,,,,,,,,,,,,,,,,,,,,,,,,,,,,,,,,
,3884728402.63162,294.942153930664,50.3786010742188,4.62852715958503E-6,7.3383880344623E-9,1,3,14.4053468704224,4.97795117630715,34.8600000143051,0.00565575588574485,0.000858122079163682,1,-1.10758855356463E-8,,,,,,,,,,,,,,,,,,,,,294.939270019531,294.945037841797,50.3786010742188,50.3786010742188,52.2319349833421,5.9397092734781,10.1052331924438,43,1,0,0,1,0.33905029296875,30.3030319213867,1,1,1,294.945037841797,0,742397504,294.942153930664,,,,,,,,,,,,,,,,,,,,,,,,,,,,,,,,,
,3884732888.74149,46.6959056854248,99.5986480712891,2.21928195437039E-5,6.81684992246925E-9,1,3,14.4053468704224,4.97834635654314,34.5899984240532,0.0271225014091843,0.00410637098039067,1,-6.01475478747165E-8,,,,,,,,,,,,,,,,,,,,,46.695255279541,46.6965560913086,99.5986480712891,99.5986480712891,52.1694047018036,5.93622420806734,6.60407876968384,43,1,0,0,1,0.338668823242188,30.3030319213867,1,1,1,46.6965560913086,0,742397696,46.6959056854248,,,,,,,,,,,,,,,,,,,,,,,,,,,,,,,,,
,3884734923.58734,101.273555755615,99.5986480712891,1.75038332733275E-5,7.60520323020251E-9,1,3,14.4053468704224,4.97831397305295,34.6099995076656,0.0213945250038996,0.00322078454452802,1,-6.2130438402758E-8,,,,,,,,,,,,,,,,,,,,,101.269172668457,101.277938842773,99.5986480712891,99.5986480712891,52.0021361986882,5.93667263902986,7.05651950836182,43,1,0,0,1,0.336685180664063,31.7693061828613,1,1,1,101.277938842773,0,742397472,101.273555755615,,,,,,,,,,,,,,,,,,,,,,,,,,,,,,,,,
,3884736963.00928,155.885726928711,99.5986480712891,1.36014676384474E-5,7.40829172670788E-9,1,3,14.4053468704224,4.97822621645796,34.6600003540516,0.0166249893388489,0.0024984933080301,1,-5.16979140230591E-8,,,,,,,,,,,,,,,,,,,,,155.881713867187,155.889739990234,99.5986480712891,99.5986480712891,52.2776602517171,5.93789016335754,7.23527383804321,43,1,0,0,1,0.337905883789063,32.7468223571777,1,1,1,155.889739990234,0,742397824,155.885726928711,,,,,,,,,,,,,,,,,,,,,,,,,,,,,,,,,
,3884739022.73983,210.515113830566,99.5986480712891,1.31340281774418E-5,6.06923702910526E-9,1,3,14.4053468704224,4.97810043670639,34.7199998795986,0.0160518645169966,0.00242038834768462,1,-4.34985175425408E-8,,,,,,,,,,,,,,,,,,,,,210.511260986328,210.518966674805,99.5986480712891,99.5986480712891,52.143610960669,5.93887874906977,7.42317724227905,43,1,0,0,1,0.334625244140625,29.3255138397217,1,1,1,210.518966674805,0,742397472,210.515113830566,,,,,,,,,,,,,,,,,,,,,,,,,,,,,,,,,
,3884741091.58254,265.145782470703,99.5986480712891,1.29516979107511E-5,8.0522132729039E-9,1,3,14.4053468704224,4.97813191111503,34.8000004887581,0.0158304277161713,0.00237863757803457,1,-4.9584012470932E-8,,,,,,,,,,,,,,,,,,,,,265.142211914062,265.149353027344,99.5986480712891,99.5986480712891,52.224900326669,5.93822376521319,8.48837471008301,43,1,0,0,1,0.338821411132812,31.7693061828613,1,1,1,265.149353027344,0,742397760,265.145782470703,,,,,,,,,,,,,,,,,,,,,,,,,,,,,,,,,
,3884746580.68,16.9001131057739,100.281593322754,0.00100636472849334,1.58264312382039E-7,1,3,14.4053468704224,4.978140864546,34.5799997448921,1.22956462836633,0.187966124104786,10,-1.28039608975917E-6,,,,,,,,,,,,,,,,,,,,,16.900032043457,16.9001941680908,100.281593322754,100.281593322754,52.199497399794,5.93730468734751,5.66736221313477,43,1,0,0,1,0.336151123046875,31.2805480957031,1,1,1,16.900032043457,0,742397536,16.9001131057739,,,,,,,,,,,,,,,,,,,,,,,,,,,,,,,,,
,3884748573.72177,71.5030059814453,100.281593322754,2.00280497803779E-5,6.97816127382101E-9,1,3,14.4053468704224,4.97817977013893,34.6000008285046,0.0244748633057503,0.00371125252240776,1,-4.96917561542031E-8,,,,,,,,,,,,,,,,,,,,,71.5001907348633,71.5058212280273,100.281593322754,100.281593322754,52.0435625102074,5.93752503797155,6.90577411651611,43,1,0,0,1,0.336761474609375,31.7693061828613,1,1,1,71.5058212280273,0,742397536,71.5030059814453,,,,,,,,,,,,,,,,,,,,,,,,,,,,,,,,,
,3884750618.59098,126.095600128174,100.281593322754,1.2967676107638E-5,6.99936242385894E-9,1,3,14.4053468704224,4.97805119687714,34.6300005912781,0.0158466756426813,0.00240047397429753,1,-3.41268700111844E-8,,,,,,,,,,,,,,,,,,,,,126.090957641602,126.100242614746,100.281593322754,100.281593322754,52.1541629456786,5.93762100651749,7.148766040802,43,1,0,0,1,0.338363647460937,31.2805480957031,1,1,1,126.100242614746,0,742397248,126.095600128174,,,,,,,,,,,,,,,,,,,,,,,,,,,,,,,,,
,3884752670.34239,180.715827941895,100.281593322754,1.18884040531213E-5,8.56791521613528E-9,1,3,14.4053468704224,4.97808542404982,34.680001437664,0.0145287815655807,0.00219518668382126,1,-3.58072099196173E-8,,,,,,,,,,,,,,,,,,,,,180.712966918945,180.718688964844,100.281593322754,100.281593322754,52.0799082363517,5.93811940118631,7.32465028762817,43,1,0,0,1,0.341796875,35.190616607666,1,1,1,180.718688964844,0,742397536,180.715827941895,,,,,,,,,,,,,,,,,,,,,,,,,,,,,,,,,
,3884754729.18014,235.346504211426,100.281593322754,1.14367914495818E-5,5.87338731775869E-9,1,3,14.4053468704224,4.97815235660618,34.7599983215332,0.0139769423525656,0.00211305258624317,1,-3.34513480527272E-8,,,,,,,,,,,,,,,,,,,,,235.342071533203,235.350936889648,100.281593322754,100.281593322754,52.1494731745632,5.93841723972861,7.65049505233765,43,1,0,0,1,0.334854125976562,30.7917900085449,1,1,1,235.350936889648,0,742397504,235.346504211426,,,,,,,,,,,,,,,,,,,,,,,,,,,,,,,,,
,3884756803.92964,289.975967407227,100.281593322754,1.11282041835609E-5,7.95791796460957E-9,1,3,14.4053468704224,4.97788034854515,34.850001335144,0.0135999104751266,0.00204853710483599,1,-3.85613476464787E-8,,,,,,,,,,,,,,,,,,,,,289.972503662109,289.979431152344,100.281593322754,100.281593322754,52.1240702476882,5.93871531155977,9.75107765197754,43,1,0,0,1,0.336227416992188,31.2805480957031,1,1,1,289.979431152344,0,742397152,289.975967407227,,,,,,,,,,,,,,,,,,,,,,,,,,,,,,,,,
,3884761299.57118,41.7323265075684,199.697326660156,4.51839435594814E-5,8.00459891387526E-9,1,3,14.4053468704224,4.97835448057426,34.5899984240532,0.0552217791441054,0.00835386396414649,1,-1.27868332273428E-7,,,,,,,,,,,,,,,,,,,,,41.7321586608887,41.732494354248,199.697326660156,199.697326660156,52.1549445741978,5.93616827707992,6.48962259292602,43,1,0,0,1,0.342025756835937,30.7917900085449,1,1,1,41.732494354248,0,742397760,41.7323265075684,,,,,,,,,,,,,,,,,,,,,,,,,,,,,,,,,
,3884763340.4249,96.3104934692383,199.697326660156,3.48069001166951E-5,9.07776808884996E-9,1,3,14.4053468704224,4.97825679621999,34.6099995076656,0.042540651475969,0.00641959517063893,1,-1.11211182489538E-7,,,,,,,,,,,,,,,,,,,,,96.3062591552734,96.3147277832031,199.697326660156,199.697326660156,52.1115641913805,5.9361279246342,7.05260038375854,43,1,0,0,1,0.338134765625,32.2580642700195,1,1,1,96.3147277832031,0,742397440,96.3104934692383,,,,,,,,,,,,,,,,,,,,,,,,,,,,,,,,,
,3884765370.85765,150.918838500977,199.697326660156,2.66005791325428E-5,7.68494651147907E-9,1,3,14.4053468704224,4.97839668698252,34.6500016748905,0.0325142182549475,0.00489344927142167,1,-9.54766980901305E-8,,,,,,,,,,,,,,,,,,,,,150.915084838867,150.922592163086,199.697326660156,199.697326660156,52.1154723339767,5.93712539480115,7.2375922203064,43,1,0,0,1,0.337677001953125,30.7917900085449,1,1,1,150.922592163086,0,742397760,150.918838500977,,,,,,,,,,,,,,,,,,,,,,,,,,,,,,,,,
,3884767424.15402,205.548210144043,199.697326660156,2.54322236916633E-5,8.6652375229936E-9,1,3,14.4053468704224,4.97821224291912,34.7100012004375,0.0310859456898396,0.00466898519338678,1,-9.88888098629785E-8,,,,,,,,,,,,,,,,,,,,,205.543930053711,205.552490234375,199.697326660156,199.697326660156,52.1854280864478,5.93676818252671,7.40840291976929,43,1,0,0,1,0.339813232421875,31.7693061828613,1,1,1,205.552490234375,0,742397568,205.548210144043,,,,,,,,,,,,,,,,,,,,,,,,,,,,,,,,,
,3884769495.88144,260.180633544922,199.697326660156,2.49596400329539E-5,8.30281061523729E-9,1,3,14.4053468704224,4.97806295234306,34.8000004887581,0.0305069330457372,0.0045826327507307,1,-9.65608148548688E-8,,,,,,,,,,,,,,,,,,,,,260.176574707031,260.184692382813,199.697326660156,199.697326660156,52.1858189007074,5.93727724427291,8.27083683013916,43,1,0,0,1,0.3399658203125,32.7468223571777,1,1,1,260.184692382813,0,742397504,260.180633544922,,,,,,,,,,,,,,,,,,,,,,,,,,,,,,,,,
,3884774996.58094,11.9332518577576,200.172927856445,0.00153625070151118,1.73609218800488E-7,1,3,14.4053468704224,4.9784235765028,34.5799997448921,1.87708145670083,0.287223062213439,10,-1.7388989869884E-6,,,,,,,,,,,,,,,,,,,,,11.9332399368286,11.9332637786865,200.172927856445,200.172927856445,52.1006213921113,5.93675871788478,5.29053640365601,43,1,0,0,1,0.339736938476562,31.2805480957031,1,1,1,11.9332399368286,0,742397600,11.9332518577576,,,,,,,,,,,,,,,,,,,,,,,,,,,,,,,,,
,3884776982.52679,66.5422630310059,200.172927856445,4.41017608491095E-5,7.73408699984184E-9,1,3,14.4053468704224,4.97841274333734,34.5899984240532,0.0538980360992983,0.0081670822370947,1,-1.14029336427147E-7,,,,,,,,,,,,,,,,,,,,,66.5411224365234,66.5434036254883,200.172927856445,200.172927856445,52.1369671182555,5.93693927503908,6.87494802474976,43,1,0,0,1,0.339889526367188,31.2805480957031,1,1,1,66.5434036254883,0,742397440,66.5422630310059,,,,,,,,,,,,,,,,,,,,,,,,,,,,,,,,,
,3884779026.4409,121.130043029785,200.172927856445,2.73373435738149E-5,7.14441851612443E-9,1,3,14.4053468704224,4.97832373520178,34.6300005912781,0.0334104046877628,0.00505278684962855,1,-7.85525678618916E-8,,,,,,,,,,,,,,,,,,,,,121.125564575195,121.134521484375,200.172927856445,200.172927856445,52.2272452122267,5.93732857784817,7.14545059204102,43,1,0,0,1,0.33721923828125,31.2805480957031,1,1,1,121.134521484375,0,742397760,121.130043029785,,,,,,,,,,,,,,,,,,,,,,,,,,,,,,,,,
,3884781079.74058,175.753242492676,200.172927856445,2.46922738083769E-5,6.92871919757433E-9,1,3,14.4053468704224,4.97818469668032,34.680001437664,0.0301756762393236,0.00456937197578101,1,-6.63235944650526E-8,,,,,,,,,,,,,,,,,,,,,175.748245239258,175.758239746094,200.172927856445,200.172927856445,52.3050172498901,5.93865371854497,7.32331562042236,43,1,0,0,1,0.339431762695313,32.2580642700195,1,1,1,175.758239746094,0,742397568,175.753242492676,,,,,,,,,,,,,,,,,,,,,,,,,,,,,,,,,
,3884783149.03469,230.378532409668,200.172927856445,2.38606049346301E-5,6.35860575760864E-9,1,3,14.4053468704224,4.97798010339151,34.7499996423721,0.0291573406214998,0.00441718426834901,1,-6.24781842327432E-8,,,,,,,,,,,,,,,,,,,,,230.374816894531,230.382247924805,200.172927856445,200.172927856445,52.2389696400151,5.93824203887804,7.60400676727295,43,1,0,0,1,0.340576171875,31.7693061828613,1,1,1,230.382247924805,0,742397376,230.378532409668,,,,,,,,,,,,,,,,,,,,,,,,,,,,,,,,,
,3884785223.77165,285.010360717773,200.172927856445,2.33192086477258E-5,7.06099545115565E-9,1,3,14.4053468704224,4.9779517169935,34.8399989306927,0.028496813193657,0.00430863013014818,1,-6.78506391777275E-8,,,,,,,,,,,,,,,,,,,,,285.006683349609,285.014038085938,200.172927856445,200.172927856445,52.214739155919,5.93907957696186,9.47501659393311,43,1,0,0,1,0.3411865234375,31.7693061828613,1,1,1,285.014038085938,0,742397760,285.010360717773,,,,,,,,,,,,,,,,,,,,,,,,,,,,,,,,,
,3884789718.47519,36.7670993804932,299.588653564453,6.89796610414178E-5,1.04521216243971E-8,1,3,14.4053468704224,4.97829841960205,34.5799997448921,0.084296511211352,0.0127920315580115,1,-1.63381188666206E-7,,,,,,,,,,,,,,,,,,,,,36.7670288085937,36.7671699523926,299.588653564453,299.588653564453,52.1260243189863,5.9373388776502,6.39324760437012,43,1,0,0,1,0.33935546875,31.2805480957031,1,1,1,36.7671699523926,0,742397696,36.7670993804932,,,,,,,,,,,,,,,,,,,,,,,,,,,,,,,,,
,3884791759.79147,91.349292755127,299.588653564453,5.10427063325283E-5,1.1147577401178E-8,1,3,14.4053468704224,4.97817219163951,34.6099995076656,0.0623780329651767,0.00944222244561016,1,-1.39831207319203E-7,,,,,,,,,,,,,,,,,,,,,91.3450241088867,91.3535614013672,299.588653564453,299.588653564453,52.1553353884574,5.93726994907954,7.04944229125977,43,1,0,0,1,0.3399658203125,30.7917900085449,1,1,1,91.3535614013672,0,742397344,91.349292755127,,,,,,,,,,,,,,,,,,,,,,,,,,,,,,,,,
,3884793784.70156,145.955757141113,299.588653564453,3.8636284173376E-5,1.10717416185549E-8,1,3,14.4053468704224,4.97824956609302,34.6500016748905,0.0472229595682055,0.00711178714251034,1,-1.34959568025216E-7,,,,,,,,,,,,,,,,,,,,,145.952545166016,145.958969116211,299.588653564453,299.588653564453,52.099839763592,5.93776841287447,7.2416729927063,43,1,0,0,1,0.340347290039063,33.2355842590332,1,1,1,145.958969116211,0,742397568,145.955757141113,,,,,,,,,,,,,,,,,,,,,,,,,,,,,,,,,
,3884795846.50758,200.585800170898,299.588653564453,3.66525083801047E-5,9.18262638212498E-9,1,3,14.4053468704224,4.97820782563944,34.7100012004375,0.044796165439292,0.00675700634765039,1,-1.19473729778728E-7,,,,,,,,,,,,,,,,,,,,,200.581008911133,200.590591430664,299.588653564453,299.588653564453,52.003308641467,5.93739351712979,7.40810632705688,43,1,0,0,1,0.338897705078125,32.7468223571777,1,1,1,200.590591430664,0,742397568,200.585800170898,,,,,,,,,,,,,,,,,,,,,,,,,,,,,,,,,
,3884797915.20631,255.212577819824,299.588653564453,3.58838394955106E-5,8.94541753593469E-9,1,3,14.4053468704224,4.97809775372233,34.790001809597,0.0438582139296606,0.00659654647411632,1,-1.32153070460831E-7,,,,,,,,,,,,,,,,,,,,,255.208023071289,255.217132568359,299.588653564453,299.588653564453,52.1268059475055,5.9379453144304,8.10017967224121,43,1,0,0,1,0.339279174804687,31.7693061828613,1,1,1,255.217132568359,0,742397280,255.212577819824,,,,,,,,,,,,,,,,,,,,,,,,,,,,,,,,,
,3884803421.8531,6.96673583984375,300.430114746094,0.00204168812135362,2.58850412804504E-7,1,3,14.4053468704224,4.99907587767587,34.5799997448921,2.50911199652127,0.383898068151957,10,-2.33934080898503E-6,,,,,,,,,,,,,,,,,,,,,6.96673583984375,6.96673583984375,300.430114746094,300.430114746094,52.2311533548228,5.93690260796559,4.52897691726685,43,1,0,0,1,0.342864990234375,30.7917900085449,1,1,1,6.96673583984375,0,742397536,6.96673583984375,,,,,,,,,,,,,,,,,,,,,,,,,,,,,,,,,
,3884805392.34983,61.58154296875,300.430114746094,7.00940933506617E-5,8.20735739294034E-9,1,3,14.4053468704224,4.99903784692681,34.5899984240532,0.0861548316283756,0.0130867747834292,1,-1.55887370477343E-7,,,,,,,,,,,,,,,,,,,,,61.5796775817871,61.5834083557129,300.430114746094,300.430114746094,52.0560685665151,5.93741360984628,6.85953617095947,43,1,0,0,1,0.343704223632812,30.3030319213867,1,1,1,61.5834083557129,0,742397504,61.58154296875,,,,,,,,,,,,,,,,,,,,,,,,,,,,,,,,,
,3884807437.8161,116.166553497314,300.430114746094,4.15922861361202E-5,9.13727466948505E-9,1,3,14.4053468704224,4.9988458954002,34.6199981868267,0.0511238027960044,0.00773797794221713,1,-1.14483408208343E-7,,,,,,,,,,,,,,,,,,,,,116.163696289062,116.169410705566,300.430114746094,300.430114746094,52.2612460528132,5.93786839877233,7.14583921432495,43,1,0,0,1,0.340499877929687,31.7693061828613,1,1,1,116.169410705566,0,742397440,116.166553497314,,,,,,,,,,,,,,,,,,,,,,,,,,,,,,,,,
,3884809478.64827,170.786392211914,300.430114746094,3.65314034376627E-5,7.82114707566795E-9,1,3,14.4053468704224,4.99886101203257,34.6699990332127,0.0449039857985169,0.00679220567269866,1,-1.0401734106094E-7,,,,,,,,,,,,,,,,,,,,,170.781112670898,170.79167175293,300.430114746094,300.430114746094,52.1201621050921,5.93858325785168,7.32367658615112,43,1,0,0,1,0.3436279296875,32.2580642700195,1,1,1,170.79167175293,0,742397600,170.786392211914,,,,,,,,,,,,,,,,,,,,,,,,,,,,,,,,,
,3884811544.92408,225.412559509277,300.430114746094,3.51605999895126E-5,7.73534689173419E-9,1,3,14.4053468704224,4.99892997077546,34.7400009632111,0.0432203975123114,0.00653384723582529,1,-1.03055194913729E-7,,,,,,,,,,,,,,,,,,,,,225.409103393555,225.416015625,300.430114746094,300.430114746094,52.1565078312363,5.93825789702462,7.56798982620239,43,1,0,0,1,0.343780517578125,32.7468223571777,1,1,1,225.416015625,0,742397568,225.412559509277,,,,,,,,,,,,,,,,,,,,,,,,,,,,,,,,,
,3884813619.17789,280.040451049805,300.430114746094,3.43905689933299E-5,7.57001248601191E-9,1,3,14.4053468704224,4.9985945655687,34.8300002515316,0.0422714849067365,0.00637989013094435,1,-1.09154294689503E-7,,,,,,,,,,,,,,,,,,,,,280.035736083984,280.045166015625,300.430114746094,300.430114746094,52.2362339401978,5.94033794009204,9.32996368408203,43,1,0,0,1,0.343399047851562,31.7693061828613,1,1,1,280.045166015625,0,742397760,280.040451049805,,,,,,,,,,,,,,,,,,,,,,,,,,,,,,,,,
,3884818128.75436,31.800407409668,399.540985107422,9.92199386072647E-5,1.31135253979166E-8,1,3,14.4053468704224,4.98878058670161,34.5799997448921,0.121596443361584,0.0185308853581819,1,-1.72341555009156E-7,,,,,,,,,,,,,,,,,,,,,31.8003940582275,31.8004207611084,399.540985107422,399.540985107422,52.0974948780344,5.93647977142496,6.28146457672119,43,1,0,0,1,0.341567993164063,31.7693061828613,1,1,1,31.8003940582275,0,742397440,31.800407409668,,,,,,,,,,,,,,,,,,,,,,,,,,,,,,,,,
,3884820156.63635,86.3841209411621,399.540985107422,6.70962890213412E-5,1.48260180535333E-8,1,3,14.4053468704224,4.98871939455414,34.6000008285046,0.0822410203297217,0.0124383428860271,1,-1.92231669160244E-7,,,,,,,,,,,,,,,,,,,,,86.3815383911133,86.3867034912109,399.540985107422,399.540985107422,52.0912418498805,5.93755770302508,7.04160451889038,43,1,0,0,1,0.341873168945313,31.2805480957031,1,1,1,86.3867034912109,0,742397568,86.3841209411621,,,,,,,,,,,,,,,,,,,,,,,,,,,,,,,,,
,3884822195.03172,140.991104125977,399.540985107422,5.02195899737598E-5,1.04561174918231E-8,1,3,14.4053468704224,4.98870654634858,34.6399992704391,0.0615560329420151,0.00930139483143207,1,-1.50657450754135E-7,,,,,,,,,,,,,,,,,,,,,140.987045288086,140.995162963867,399.540985107422,399.540985107422,52.1975433284959,5.93762122796194,7.24559640884399,43,1,0,0,1,0.341339111328125,31.7693061828613,1,1,1,140.995162963867,0,742397728,140.991104125977,,,,,,,,,,,,,,,,,,,,,,,,,,,,,,,,,
,3884824254.8849,195.616897583008,399.540985107422,4.71293328537906E-5,1.01649383145762E-8,1,3,14.4053468704224,4.98852321991056,34.6999987959862,0.057765449950537,0.00872713946146982,1,-1.42568228165884E-7,,,,,,,,,,,,,,,,,,,,,195.613357543945,195.62043762207,399.540985107422,399.540985107422,52.2284176550055,5.93823529261591,7.41034603118897,43,1,0,0,1,0.340652465820313,31.2805480957031,1,1,1,195.62043762207,0,742397536,195.616897583008,,,,,,,,,,,,,,,,,,,,,,,,,,,,,,,,,
,3884826323.15734,250.244331359863,399.540985107422,4.59807694232198E-5,1.00915977602322E-8,1,3,14.4053468704224,4.98847442306488,34.7799994051456,0.0563582840343384,0.00850542802738447,1,-1.46367379065295E-7,,,,,,,,,,,,,,,,,,,,,250.239791870117,250.248870849609,399.540985107422,399.540985107422,52.1221161763901,5.93872308222549,7.96933507919311,43,1,0,0,1,0.341339111328125,32.7468223571777,1,1,1,250.248870849609,0,742397312,250.244331359863,,,,,,,,,,,,,,,,,,,,,,,,,,,,,,,,,
,3884831830.60103,2.00012302398682,400.309265136719,0.00221646557018589,8.88811375077192E-6,1,3,14.4053468704224,4.97833061477964,34.5799997448921,2.70428097353456,0.439400548940046,10,1.79663996601075E-5,,,,,,,,,,,,,,,,,,,,,2.00012302398682,2.00012302398682,400.309265136719,400.309265136719,52.1162539624959,5.93649823167574,2.65522408485413,43,1,0,0,1,0.339202880859375,28.3479976654053,1,1,1,2.00012302398682,0,742397472,2.00012302398682,,,,,,,,,,,,,,,,,,,,,,,,,,,,,,,,,
,3884833817.7563,56.6205043792725,400.309265136719,9.72817996763579E-5,1.37465045903353E-8,1,3,14.4053468704224,4.9782968521643,34.5899984240532,0.118878294870438,0.0180714169032263,1,-2.0515174164508E-7,,,,,,,,,,,,,,,,,,,,,56.6189460754395,56.6220626831055,400.309265136719,400.309265136719,52.169013887544,5.93769594751252,6.82525110244751,43,1,0,0,1,0.340118408203125,31.7693061828613,1,1,1,56.6221580505371,0,742397728,56.6205043792725,,,,,,,,,,,,,,,,,,,,,,,,,,,,,,,,,
,3884835860.60611,111.199520111084,400.309265136719,5.54135293694367E-5,1.04582643953135E-8,1,3,14.4053468704224,4.97826673312563,34.6199981868267,0.0677214587480973,0.0102500446230091,1,-1.52618817640854E-7,,,,,,,,,,,,,,,,,,,,,111.196319580078,111.20272064209,400.309265136719,400.309265136719,52.1889454147844,5.93781131598255,7.14611101150513,43,1,0,0,1,0.342559814453125,31.2805480957031,1,1,1,111.20272064209,0,742397504,111.199520111084,,,,,,,,,,,,,,,,,,,,,,,,,,,,,,,,,
,3884837908.36792,165.816825866699,400.309265136719,4.72175642396278E-5,1.06433554430103E-8,1,3,14.4053468704224,4.97822326629332,34.6699990332127,0.0577038359631427,0.00873742330289267,1,-1.2716158333997E-7,,,,,,,,,,,,,,,,,,,,,165.813919067383,165.819732666016,400.309265136719,400.309265136719,52.153772131419,5.93724537044497,7.32133913040161,43,1,0,0,1,0.3387451171875,31.7693061828613,1,1,1,165.819732666016,0,742397408,165.816825866699,,,,,,,,,,,,,,,,,,,,,,,,,,,,,,,,,
,3884839964.74793,220.446929931641,400.309265136719,4.5225750953058E-5,1.04070104642077E-8,1,3,14.4053468704224,4.97813372542625,34.7299985587597,0.0552691165677818,0.00836323018462485,1,-1.2622262532675E-7,,,,,,,,,,,,,,,,,,,,,220.443328857422,220.450531005859,400.309265136719,400.309265136719,52.3362823906594,5.93794708468743,7.5454363822937,43,1,0,0,1,0.333023071289063,31.2805480957031,1,1,1,220.450531005859,0,742397792,220.446929931641,,,,,,,,,,,,,,,,,,,,,,,,,,,,,,,,,
,3884842038.55279,275.076431274414,400.309265136719,4.41838543385836E-5,1.12953398081055E-8,1,3,14.4053468704224,4.97777846149702,34.8200015723705,0.0539922596746252,0.00815806192576064,1,-1.32880493633041E-7,,,,,,,,,,,,,,,,,,,,,275.071746826172,275.081115722656,400.309265136719,400.309265136719,52.1709679588421,5.94054379842395,9.19511795043945,43,1,0,0,1,0.3363037109375,31.2805480957031,1,1,1,275.081115722656,0,742397504,275.076431274414,,,,,,,,,,,,,,,,,,,,,,,,,,,,,,,,,
,3884846558.16521,26.8334503173828,499.62744140625,0.000200907132107161,2.38059099214198E-8,1,3,14.4053468704224,4.97831377441022,34.5799997448921,0.245463234551519,0.0376218110223179,1,-1.7777356129799E-7,,,,,,,,,,,,,,,,,,,,,26.833324432373,26.8335762023926,499.62744140625,499.62744140625,52.1389211895536,5.9372342873076,6.14157676696777,43,1,0,0,1,0.337677001953125,31.7693061828613,1,1,1,26.833324432373,0,742397568,26.8334503173828,,,,,,,,,,,,,,,,,,,,,,,,,,,,,,,,,
,3884848578.55957,81.4253540039063,499.62744140625,8.26572651026276E-5,2.35742566834341E-8,1,3,14.4053468704224,4.97807689883904,34.6000008285046,0.101008581404071,0.0153038497002967,1,-2.15172037150644E-7,,,,,,,,,,,,,,,,,,,,,81.4220657348633,81.4286422729492,499.62744140625,499.62744140625,52.1729220301401,5.93807787750131,7.03424739837646,43,1,0,0,1,0.340042114257812,32.2580642700195,1,1,1,81.4286422729492,0,742397600,81.4253540039063,,,,,,,,,,,,,,,,,,,,,,,,,,,,,,,,,
,3884850614.87703,136.025497436523,499.62744140625,6.09051584968265E-5,1.43419479442616E-8,1,3,14.4053468704224,4.97803814076233,34.6399992704391,0.0744290907260382,0.0112584419427135,1,-1.73217738767514E-7,,,,,,,,,,,,,,,,,,,,,136.021911621094,136.029083251953,499.62744140625,499.62744140625,52.331592619544,5.93845741774867,7.24254894256592,43,1,0,0,1,0.334548950195313,31.7693061828613,1,1,1,136.029083251953,0,742397472,136.025497436523,,,,,,,,,,,,,,,,,,,,,,,,,,,,,,,,,
,3884852668.2092,190.650459289551,499.62744140625,5.64470993788977E-5,1.32139638017749E-8,1,3,14.4053468704224,4.97795142171403,34.6999987959862,0.0689766902733781,0.0104519697550492,1,-1.45914643924978E-7,,,,,,,,,,,,,,,,,,,,,190.646057128906,190.654861450195,499.62744140625,499.62744140625,52.133449789919,5.93963034842944,7.41515874862671,43,1,0,0,1,0.336456298828125,32.2580642700195,1,1,1,190.654861450195,0,742397312,190.650459289551,,,,,,,,,,,,,,,,,,,,,,,,,,,,,,,,,
,3884854736.97718,245.278877258301,499.62744140625,5.48056551785593E-5,1.16520423895504E-8,1,3,14.4053468704224,4.97798477402681,34.7700007259846,0.0669779561876831,0.0101063889410947,1,-1.75842369435763E-7,,,,,,,,,,,,,,,,,,,,,245.274887084961,245.282867431641,499.62744140625,499.62744140625,52.1678414447651,5.93950143319165,7.86376285552979,43,1,0,0,1,0.336456298828125,32.2580642700195,1,1,1,245.282867431641,0,742397568,245.278877258301,,,,,,,,,,,,,,,,,,,,,,,,,,,,,,,,,
,3884856823.21762,299.911163330078,499.62744140625,5.39652667698356E-5,1.26652410084011E-8,1,3,14.4053468704224,4.97774927253268,34.8699986934662,0.0659489767138721,0.00993506664009453,1,-1.85994391141706E-7,,,,,,,,,,,,,,,,,,,,,299.90673828125,299.915588378906,499.62744140625,499.62744140625,52.1819107581113,5.94187553943736,10.0666399002075,43,1,0,0,1,0.339431762695313,31.7693061828613,1,1,1,299.915588378906,0,742397504,299.911163330078,,,,,,,,,,,,,,,,,,,,,,,,,,,,,,,,,
,3884862235.55703,51.6582565307617,500.285980224609,0.000126063998563772,1.71298529058655E-8,1,3,14.4053468704224,4.97837985602289,34.5899984240532,0.154045754239523,0.023470266594915,1,-2.23594416765253E-7,,,,,,,,,,,,,,,,,,,,,51.6575012207031,51.6590118408203,500.285980224609,500.285980224609,52.1959800714574,5.93871112558103,6.73863887786865,43,1,0,0,1,0.338134765625,32.2580642700195,1,1,1,51.6590118408203,0,742397728,51.6582565307617,,,,,,,,,,,,,,,,,,,,,,,,,,,,,,,,,
,3884864280.34664,106.23420715332,500.285980224609,6.9018154552973E-5,1.22292994914287E-8,1,3,14.4053468704224,4.97813558291035,34.6199981868267,0.0843418950422449,0.0127843242448695,1,-1.75146646615868E-7,,,,,,,,,,,,,,,,,,,,,106.231376647949,106.237037658691,500.285980224609,500.285980224609,52.2436594111305,5.93990297816237,7.14701366424561,43,1,0,0,1,0.33660888671875,30.7917900085449,1,1,1,106.237037658691,0,742397408,106.23420715332,,,,,,,,,,,,,,,,,,,,,,,,,,,,,,,,,
,3884866318.7841,160.850959777832,500.285980224609,5.71211643737322E-5,1.16352960792485E-8,1,3,14.4053468704224,4.97820735334508,34.6600003540516,0.0698079983304346,0.0105606471960462,1,-1.61487753373962E-7,,,,,,,,,,,,,,,,,,,,,160.847702026367,160.854217529297,500.285980224609,500.285980224609,52.2667174524478,5.94078883981009,7.33109092712402,43,1,0,0,1,0.339202880859375,32.2580642700195,1,1,1,160.854217529297,0,742397664,160.850959777832,,,,,,,,,,,,,,,,,,,,,,,,,,,,,,,,,
,3884868380.58918,215.480545043945,500.285980224609,5.44080010328734E-5,9.54381116174812E-9,1,3,14.4053468704224,4.97831132798432,34.7299985587597,0.0664950984701902,0.0100533162037444,1,-1.58737815709382E-7,,,,,,,,,,,,,,,,,,,,,215.475280761719,215.485809326172,500.285980224609,500.285980224609,52.1920719288613,5.94046430423805,7.5374550819397,43,1,0,0,1,0.336380004882812,32.2580642700195,1,1,1,215.485809326172,0,742397504,215.480545043945,,,,,,,,,,,,,,,,,,,,,,,,,,,,,,,,,
,3884870454.83503,270.138565063477,500.285980224609,5.30633045342926E-5,1.03083051744241E-8,1,3,14.4053468704224,4.97804176001069,34.8099991679192,0.0648470588666814,0.00980217309187978,1,-1.56396963018803E-7,,,,,,,,,,,,,,,,,,,,,270.131713867187,270.145416259766,500.285980224609,500.285980224609,52.3042356213709,5.94119133195119,8.87716674804687,43,1,0,0,1,0.337677001953125,31.2805480957031,1,1,1,270.145416259766,0,742397792,270.138565063477,,,,,,,,,,,,,,,,,,,,,,,,,,,,,,,,,
,3884874989.88205,21.8669052124023,699.593078613281,0.000313740756234503,3.1204070205243E-8,1,3,14.4053468704224,4.98865494034202,34.5799997448921,0.384409244569921,0.0590749529548069,1,-1.52363010130305E-7,,,,,,,,,,,,,,,,,,,,,21.8667736053467,21.867036819458,699.593078613281,699.593078613281,52.3034539928517,5.94023358666378,5.95991468429565,43,1,0,0,1,0.340805053710937,32.2580642700195,1,1,1,21.867036819458,0,742397600,21.8669052124023,,,,,,,,,,,,,,,,,,,,,,,,,,,,,,,,,
,3884876996.28705,76.462532043457,699.593078613281,0.00010945527573026,1.9572760841215E-8,1,3,14.4053468704224,4.9884836531689,34.6000008285046,0.134136550846869,0.0203915416780826,1,-2.30326022519255E-7,,,,,,,,,,,,,,,,,,,,,76.4606781005859,76.4643859863281,699.593078613281,699.593078613281,52.1799566868132,5.94048302658661,7.02146100997925,43,1,0,0,1,0.341033935546875,32.2580642700195,1,1,1,76.4643859863281,0,742397312,76.462532043457,,,,,,,,,,,,,,,,,,,,,,,,,,,,,,,,,
,3884879031.658,131.059417724609,699.593078613281,7.94662782876681E-5,1.89944593298636E-8,1,3,14.4053468704224,4.98829412991536,34.6300005912781,0.0973874436740188,0.0147562671234287,1,-2.06021837887408E-7,,,,,,,,,,,,,,,,,,,,,131.056182861328,131.062652587891,699.593078613281,699.593078613281,52.2538205818805,5.94131250639011,7.2510232925415,43,1,0,0,1,0.337982177734375,32.2580642700195,1,1,1,131.062652587891,0,742397728,131.059417724609,,,,,,,,,,,,,,,,,,,,,,,,,,,,,,,,,
,3884881079.54887,185.681037902832,699.593078613281,7.22231145893526E-5,1.59134885514039E-8,1,3,14.4053468704224,4.98817445658081,34.6900001168251,0.0885088595179384,0.0134042380045538,1,-1.92615904294215E-7,,,,,,,,,,,,,,,,,,,,,185.678024291992,185.684051513672,699.593078613281,699.593078613281,52.2135667131401,5.94212599942868,7.41589498519897,43,1,0,0,1,0.33660888671875,34.2131004333496,1,1,1,185.684051513672,0,742397632,185.681037902832,,,,,,,,,,,,,,,,,,,,,,,,,,,,,,,,,
,3884883147.3075,240.312004089355,699.593078613281,6.95781506585378E-5,1.55976274848461E-8,1,3,14.4053468704224,4.98830664000433,34.7599983215332,0.0852711659840983,0.0129103481367966,1,-1.88399138592669E-7,,,,,,,,,,,,,,,,,,,,,240.30712890625,240.316879272461,699.593078613281,699.593078613281,52.1721404016209,5.94089419882593,7.78738689422607,43,1,0,0,1,0.339202880859375,32.2580642700195,1,1,1,240.316879272461,0,742397440,240.312004089355,,,,,,,,,,,,,,,,,,,,,,,,,,,,,,,,,
,3884885219.64795,294.938888549805,699.593078613281,6.81773535273155E-5,1.50746152281302E-8,1,3,14.4053468704224,4.98813637169389,34.8600000143051,0.0835558134158601,0.0126150111274421,1,-2.13026376357329E-7,,,,,,,,,,,,,,,,,,,,,294.935699462891,294.942077636719,699.593078613281,699.593078613281,52.2424869683517,5.94247302532338,10.1011075973511,43,1,0,0,1,0.336151123046875,33.2355842590332,1,1,1,294.942077636719,0,742397408,294.938888549805,,,,,,,,,,,,,,,,,,,,,,,,,,,,,,,,,
,3884890630.91103,46.695743560791,700.239379882813,0.000179031052208254,2.79057493035223E-8,1,3,14.4053468704224,5.00982646053603,34.5899984240532,0.220684250310842,0.0337188924955586,1,-2.41710748086753E-7,,,,,,,,,,,,,,,,,,,,,46.6953239440918,46.6961631774902,700.239379882813,700.239379882813,52.1408752608517,5.93888897011218,6.61686134338379,43,1,0,0,1,0.345382690429687,31.7693061828613,1,1,1,46.6961631774902,0,742397760,46.695743560791,,,,,,,,,,,,,,,,,,,,,,,,,,,,,,,,,
,3884892677.82488,101.274017333984,700.239379882813,9.22583924016486E-5,1.58130085909599E-8,1,3,14.4053468704224,5.00962119632899,34.6099995076656,0.113732490863204,0.0172723920238218,1,-2.07862602304825E-7,,,,,,,,,,,,,,,,,,,,,101.26921081543,101.278823852539,700.239379882813,700.239379882813,52.1498639888228,5.94009272672651,7.13868951797485,43,1,0,0,1,0.342254638671875,32.7468223571777,1,1,1,101.278823852539,0,742397120,101.274017333984,,,,,,,,,,,,,,,,,,,,,,,,,,,,,,,,,
,3884894719.70142,155.88907623291,700.239379882813,7.41277079476158E-5,1.28465174664797E-8,1,3,14.4053468704224,5.0096451775015,34.6600003540516,0.0913861795785666,0.0138530019746525,1,-1.87380855018423E-7,,,,,,,,,,,,,,,,,,,,,155.883834838867,155.894317626953,700.239379882813,700.239379882813,52.2968101504382,5.94025198441137,7.33632326126099,43,1,0,0,1,0.344161987304687,32.2580642700195,1,1,1,155.894317626953,0,742397696,155.88907623291,,,,,,,,,,,,,,,,,,,,,,,,,,,,,,,,,
,3884896788.48014,210.515998840332,700.239379882813,6.97917506882125E-5,1.22655497416421E-8,1,3,14.4053468704224,5.00937855607176,34.7199998795986,0.0860331841505837,0.0130493079090761,1,-1.70272234909878E-7,,,,,,,,,,,,,,,,,,,,,210.511016845703,210.520980834961,700.239379882813,700.239379882813,52.1823015723709,5.94071871067301,7.5221266746521,43,1,0,0,1,0.342178344726562,31.7693061828613,1,1,1,210.520980834961,0,742397408,210.515998840332,,,,,,,,,,,,,,,,,,,,,,,,,,,,,,,,,
,3884898857.19646,265.144775390625,700.239379882813,6.77495723801514E-5,1.16344399401772E-8,1,3,14.4053468704224,5.00946211567511,34.8000004887581,0.0835202357385889,0.0126513346338643,1,-1.78623757985319E-7,,,,,,,,,,,,,,,,,,,,,265.140411376953,265.149139404297,700.239379882813,700.239379882813,52.2905571222844,5.94110316018172,8.59668731689453,43,1,0,0,1,0.347747802734375,32.2580642700195,1,1,1,265.149139404297,0,742397280,265.144775390625,,,,,,,,,,,,,,,,,,,,,,,,,,,,,,,,,
,3884903418.62821,16.8996896743774,999.657287597656,0.000435786489318112,5.23936499114904E-8,1,3,14.4053468704224,4.98868113322202,34.5799997448921,0.533885589296171,0.0824675134701597,1,1.2439947678992E-7,,,,,,,,,,,,,,,,,,,,,16.8995094299316,16.8998699188232,999.657287597656,999.657287597656,52.275706180419,5.93836186980853,5.70500373840332,43,1,0,0,1,0.34149169921875,31.7693061828613,1,1,1,16.8998699188232,0,742397248,16.8996896743774,,,,,,,,,,,,,,,,,,,,,,,,,,,,,,,,,
,3884905406.63203,71.5017776489258,999.657287597656,0.000142702871380192,2.15722935932376E-8,1,3,14.4053468704224,4.98864386656313,34.6000008285046,0.174886647198803,0.0266023299330755,1,-2.87586187081879E-7,,,,,,,,,,,,,,,,,,,,,71.4998321533203,71.5037231445313,999.657287597656,999.657287597656,52.2307625405632,5.93879939138408,7.00555610656738,43,1,0,0,1,0.340652465820313,33.7243423461914,1,1,1,71.5037231445313,0,742397792,71.5017776489258,,,,,,,,,,,,,,,,,,,,,,,,,,,,,,,,,
,3884907448.02009,126.09549331665,999.657287597656,0.000100300788853963,1.82129992048365E-8,1,3,14.4053468704224,4.98840379511007,34.6300005912781,0.12292195037417,0.0186409218981549,1,-2.47565982895463E-7,,,,,,,,,,,,,,,,,,,,,126.091415405273,126.099571228027,999.657287597656,999.657287597656,52.0658389230055,5.93955289791654,7.25133943557739,43,1,0,0,1,0.341110229492188,32.2580642700195,1,1,1,126.099571228027,0,742397536,126.09549331665,,,,,,,,,,,,,,,,,,,,,,,,,,,,,,,,,
,3884909504.30078,180.718421936035,999.657287597656,8.80762733318132E-5,1.80448734519024E-8,1,3,14.4053468704224,4.98829148121274,34.680001437664,0.107941004557274,0.0163425631330555,1,-2.3854825757549E-7,,,,,,,,,,,,,,,,,,,,,180.713775634766,180.723068237305,999.657287597656,999.657287597656,52.1705771445824,5.94043806588651,7.41738986968994,43,1,0,0,1,0.341720581054687,31.7693061828613,1,1,1,180.723068237305,0,742397536,180.718421936035,,,,,,,,,,,,,,,,,,,,,,,,,,,,,,,,,
,3884911567.14785,235.34757232666,999.657287597656,8.38634202072702E-5,1.97869039563782E-8,1,3,14.4053468704224,4.98833479117693,34.7599983215332,0.102780485789442,0.0155529068881276,1,-2.33790360285384E-7,,,,,,,,,,,,,,,,,,,,,235.343002319336,235.352142333984,999.657287597656,999.657287597656,52.115081519717,5.93966219984309,7.7258563041687,43,1,0,0,1,0.34210205078125,31.7693061828613,1,1,1,235.352142333984,0,742397440,235.34757232666,,,,,,,,,,,,,,,,,,,,,,,,,,,,,,,,,
,3884913641.37018,289.976287841797,999.657287597656,8.15194495214802E-5,1.76381407640996E-8,1,3,14.4053468704224,4.98844657251657,34.850001335144,0.0999128549611743,0.0151060621158218,1,-2.37554022117561E-7,,,,,,,,,,,,,,,,,,,,,289.971343994141,289.981231689453,999.657287597656,999.657287597656,52.2987642217363,5.94046470790043,9.76548194885254,43,1,0,0,1,0.339279174804687,31.7693061828613,1,1,1,289.981231689453,0,742397568,289.976287841797,,,,,,,,,,,,,,,,,,,,,,,,,,,,,,,,,
,3884919055.71695,41.7325744628906,1000.47442626953,0.000254315500652413,4.90237546391486E-8,1,3,14.4053468704224,4.97841087860532,34.5899984240532,0.310754860510651,0.0474286795788418,1,-3.85198041502999E-7,,,,,,,,,,,,,,,,,,,,,41.7320518493652,41.733097076416,1000.47442626953,1000.47442626953,52.2139575273998,5.93843052808802,6.49371528625488,43,1,0,0,1,0.339279174804687,31.2805480957031,1,1,1,41.733097076416,0,742397472,41.7325744628906,,,,,,,,,,,,,,,,,,,,,,,,,,,,,,,,,
,3884921095.17257,96.3087005615234,1000.47442626953,0.000118915876510592,1.78804124661429E-8,1,3,14.4053468704224,4.97820279857982,34.6099995076656,0.145312750744887,0.0220801535119849,1,-2.58554706760934E-7,,,,,,,,,,,,,,,,,,,,,96.3050765991211,96.3123245239258,1000.47442626953,1000.47442626953,52.1686230732844,5.93911829304263,7.14198684692383,43,1,0,0,1,0.339202880859375,32.7468223571777,1,1,1,96.3123245239258,0,742397504,96.3087005615234,,,,,,,,,,,,,,,,,,,,,,,,,,,,,,,,,
,3884923130.94269,150.922142028809,1000.47442626953,9.19500923095949E-5,1.81333595105371E-8,1,3,14.4053468704224,4.97821489049743,34.6500016748905,0.112368861996945,0.0170254838004176,1,-2.390161696165E-7,,,,,,,,,,,,,,,,,,,,,150.918319702148,150.925964355469,1000.47442626953,1000.47442626953,52.2120034561017,5.93918313188016,7.33110523223877,43,1,0,0,1,0.336227416992188,32.7468223571777,1,1,1,150.925964355469,0,742397600,150.922142028809,,,,,,,,,,,,,,,,,,,,,,,,,,,,,,,,,
,3884925190.29746,205.548721313477,1000.47442626953,8.51054118277433E-5,1.59853749610426E-8,1,3,14.4053468704224,4.97816490015588,34.7100012004375,0.104003000280462,0.0157563905916511,1,-2.2246069332275E-7,,,,,,,,,,,,,,,,,,,,,205.544372558594,205.553070068359,1000.47442626953,1000.47442626953,52.1936351858998,5.93922160600353,7.51314973831177,43,1,0,0,1,0.340194702148438,34.2131004333496,1,1,1,205.553070068359,0,742397344,205.548721313477,,,,,,,,,,,,,,,,,,,,,,,,,,,,,,,,,
,3884927259.0867,260.176391601562,1000.47442626953,8.19964899466372E-5,1.29688119384127E-8,1,3,14.4053468704224,4.97801410722959,34.8000004887581,0.100201165393042,0.0151693778811738,1,-2.23163542726345E-7,,,,,,,,,,,,,,,,,,,,,260.172241210938,260.180541992187,1000.47442626953,1000.47442626953,52.3476160041882,5.94057195992324,8.37196826934814,43,1,0,0,1,0.340652465820313,32.2580642700195,1,1,1,260.180541992187,0,742397664,260.176391601562,,,,,,,,,,,,,,,,,,,,,,,,,,,,,,,,,
,3884928783.72936,299.909423828125,1000.47442626953,8.05088813806863E-5,1.45456643058593E-8,1,3,14.4053468704224,4.97789834600971,34.8699986934662,0.098381879151393,0.0148820399596272,1,-2.28649078012732E-7,,,,,,,,,,,,,,,,,,,,,299.903533935547,299.915313720703,1000.47442626953,1000.47442626953,52.1553353884574,5.94150175582257,10.4105625152588,43,1,0,0,1,0.337295532226562,32.2580642700195,1,1,1,299.915313720703,0,742397216,299.909423828125,,,,,,,,,,,,,,,,,,,,,,,,,,,,,,,,,